<?xml version="1.0"?>
<robot xmlns:xacro="http://ros.org/wiki/xacro">

  <xacro:macro name="robotiq_gripper"  params="prefix">
    <link name="robotiq_arg2f_base_link">
      <inertial>
        <origin xyz="8.625E-08 -4.6583E-06 0.03145" rpy="0 0 0" />
        <mass value="0.22652" />
        <inertia ixx="0.00020005" ixy="0" ixz="0" iyy="0.00017832" iyz="0" izz="0.00013478" />
      </inertial>
      <visual>
        <origin xyz="0 0 0" rpy="0 0 1.57" />
        <geometry>
          <mesh filename="package://robotiq_140_gripper_description/meshes/GRIPPER_base_axis.stl" scale="0.001 0.001 0.001"/>
        </geometry>
        <material name="">
          <color rgba="0.1 0.1 0.1 1" />
        </material>
      </visual>
      <collision>
        <origin xyz="0 0 0" rpy="0 0 1.57" />
        <geometry>
          <mesh filename="package://robotiq_140_gripper_description/meshes/GRIPPER_base_axis.stl" scale="0.001 0.001 0.001"/>
        </geometry>
      </collision>
    </link>
    <gazebo reference="robotiq_arg2f_base_link">
      <material>Gazebo/Grey</material>
      <selfCollide>True</selfCollide>
    </gazebo>

    <link name="left_outer_knuckle">
      <inertial>
        <!--<origin xyz="-0.000200000000003065 0.0199435877845359 0.0292245259211331" rpy="0 0 0" />-->
        <mass value="0.00853198276973456" />
        <inertia
            ixx="2.88840278e-09"
            ixy="0"
            ixz="0"
            iyy="2.80689245e-10"
            iyz="0"
            izz="2.79961804e-09" />
      </inertial>
      <visual>
        <origin xyz="0 0 0" rpy="0 0 0" />
        <geometry>
          <mesh filename="package://robotiq_140_gripper_description/meshes/robotiq_arg2f_140_outer_knuckle.stl" />
        </geometry>
        <material name="">
          <color rgba="0.792156862745098 0.819607843137255 0.933333333333333 1" />
        </material>
      </visual>
      <collision>
        <origin xyz="0 0 0" rpy="0 0 0" />
        <geometry>
          <mesh filename="package://robotiq_140_gripper_description/meshes/robotiq_arg2f_140_outer_knuckle.stl" />
        </geometry>
      </collision>
    </link>
    <gazebo reference="left_outer_knuckle">
      <material>Gazebo/Grey</material>
      <selfCollide>True</selfCollide>
    </gazebo>

    <link name="right_outer_knuckle">
      <inertial>
        <origin xyz="0 0 0" rpy="0 0 0" />
        <mass value="0.00853198276973456" />
        <inertia
            ixx="2.88840278e-09"
            ixy="0"
            ixz="0"
            iyy="2.80689245e-10"
            iyz="0"
            izz="2.79961804e-09" />
      </inertial>
      <visual>
        <origin xyz="0 0 0" rpy="0 0 0" />
        <geometry>
          <mesh filename="package://robotiq_140_gripper_description/meshes/robotiq_arg2f_140_outer_knuckle.stl" />
        </geometry>
        <material name="">
          <color rgba="0.792156862745098 0.819607843137255 0.933333333333333 1" />
        </material>
      </visual>
      <collision>
        <origin xyz="0 0 0" rpy="0 0 0" />
        <geometry>
          <mesh filename="package://robotiq_140_gripper_description/meshes/robotiq_arg2f_140_outer_knuckle.stl" />
        </geometry>
      </collision>
    </link>
    <gazebo reference="right_outer_knuckle">
      <material>Gazebo/Grey</material>
      <selfCollide>True</selfCollide>
    </gazebo>

    <link name="left_inner_knuckle">
      <inertial>
        <origin xyz="0 0 0" rpy="0 0 0" />
        <mass value="0.0271177346495152" />
        <inertia
            ixx="2.61910379223783E-05"
            ixy="0"
            ixz="0"
            iyy="2.8270243746167E-06"
            iyz="0"
            izz="2.83695868220296E-05" />
      </inertial>
      <visual>
        <origin xyz="0 0 0" rpy="0 0 0" />
        <geometry>
          <mesh filename="package://robotiq_140_gripper_description/meshes/robotiq_arg2f_140_inner_knuckle.stl" />
        </geometry>
        <material name="">
          <color rgba="0.1 0.1 0.1 1" />
        </material>
      </visual>
    </link>
    <gazebo reference="left_inner_knuckle">
      <material>Gazebo/Grey</material>
      <selfCollide>False</selfCollide>
    </gazebo>

    <link name="right_inner_knuckle">
      <inertial>
        <origin xyz="0 0 0" rpy="0 0 0" />
        <mass value="0.0271177346495152" />
        <inertia
            ixx="2.61910379223783E-05"
            ixy="0"
            ixz="0"
            iyy="2.8270243746167E-06"
            iyz="0"
            izz="2.83695868220296E-05" />
      </inertial>
      <visual>
        <origin xyz="0 0 0" rpy="0 0 0" />
        <geometry>
          <mesh filename="package://robotiq_140_gripper_description/meshes/robotiq_arg2f_140_inner_knuckle.stl" />
        </geometry>
        <material name="">
          <color rgba="0.1 0.1 0.1 1" />
        </material>
      </visual>

    </link>
    <gazebo reference="right_inner_knuckle">
      <material>Gazebo/Grey</material>
      <selfCollide>False</selfCollide>
    </gazebo>

    <link name="left_inner_finger">
      <inertial>
        <origin xyz="0 0 0" rpy="0 0 0" />
        <mass value="0.0104003125914103" />
        <inertia
            ixx="2.71909453810972E-06"
            ixy="0"
            ixz="0"
            iyy="7.69100314106116E-07"
            iyz="0"
            izz="2.30315190420171E-06" />
      </inertial>
      <visual>
        <origin xyz="0 0 0" rpy="0 0 0" />
        <geometry>
          <mesh filename="package://robotiq_140_gripper_description/meshes/robotiq_arg2f_140_inner_finger.stl" scale="0.001 0.001 0.001" />
        </geometry>
        <material name="">
          <color rgba="0.1 0.1 0.1 1" />
        </material>
      </visual>
      <collision>
        <origin xyz="0 0 0" rpy="0 0 0" />
        <geometry>
          <mesh filename="package://robotiq_140_gripper_description/meshes/robotiq_arg2f_140_inner_finger.stl" scale="0.001 0.001 0.001" />
        </geometry>
      </collision>
    </link>
    <gazebo reference="left_inner_finger">
      <material>Gazebo/Grey</material>
      <selfCollide>True</selfCollide>
    </gazebo>

    <link name="right_inner_finger">
      <inertial>
        <origin xyz="0.0 0.031506174 -0.017648840" rpy="0 0 0" />
        <mass value="0.0104003125914103" />
        <inertia
            ixx="6.06863499e-06"
            ixy="0"
            ixz="0"
            iyy="7.46305064e-07"
            iyz="0"
            izz="6.21796490e-06" />
      </inertial>
      <visual>
        <origin xyz="0 0 0" rpy="0 0 0" />
        <geometry>
          <mesh filename="package://robotiq_140_gripper_description/meshes/robotiq_arg2f_140_inner_finger.stl" scale="0.001 0.001 0.001"/>
        </geometry>
        <material name="">
          <color rgba="0.1 0.1 0.1 1" />
        </material>
      </visual>
      <collision>
        <origin xyz="0 0 0" rpy="0 0 0" />
        <geometry>
          <mesh filename="package://robotiq_140_gripper_description/meshes/robotiq_arg2f_140_inner_finger.stl" scale="0.001 0.001 0.001"/>
        </geometry>
      </collision>
    </link>
    <gazebo reference="right_inner_finger">
      <material>Gazebo/Grey</material>
      <selfCollide>True</selfCollide>
    </gazebo>

    <link name="left_outer_finger">
      <inertial>
        <origin xyz="0 0 0" rpy="0 0 0" />
        <mass value="0.022614240507152" />
        <inertia
            ixx="1.52518312458174E-05"
            ixy="0"
            ixz="0"
            iyy="6.17694243867776E-06"
            iyz="0"
            izz="1.16494917907219E-05" />
      </inertial>
      <visual>
        <origin xyz="0 0 0" rpy="0 0 0" />
        <geometry>
          <mesh filename="package://robotiq_140_gripper_description/meshes/robotiq_arg2f_140_outer_finger.stl" />
        </geometry>
        <material name="">
          <color rgba="0.1 0.1 0.1 1" />
        </material>
      </visual>
      <collision>
        <origin xyz="0 0 0" rpy="0 0 0" />
        <geometry>
          <mesh filename="package://robotiq_140_gripper_description/meshes/robotiq_arg2f_140_outer_finger.stl" />
        </geometry>
      </collision>
    </link>
    <gazebo reference="left_outer_finger">
      <material>Gazebo/Grey</material>
      <selfCollide>True</selfCollide>
    </gazebo>

    <link name="right_outer_finger">
      <inertial>
        <origin xyz="-0.0002009,  0.0396149, -0.0161363" rpy="0 0 0" />
        <mass value="0.022614240507152" />
        <inertia
            ixx="1.52518312458174E-05"
            ixy="0"
            ixz="0"
            iyy="6.17694243867776E-06"
            iyz="0"
            izz="1.16494917907219E-05" />
      </inertial>
      <visual>
        <origin xyz="0 0 0" rpy="0 0 0" />
        <geometry>
          <mesh filename="package://robotiq_140_gripper_description/meshes/robotiq_arg2f_140_outer_finger.stl" />
        </geometry>
        <material name="">
          <color rgba="0.1 0.1 0.1 1" />
        </material>
      </visual>
      <collision>
        <origin xyz="0 0 0" rpy="0 0 0" />
        <geometry>
          <mesh filename="package://robotiq_140_gripper_description/meshes/robotiq_arg2f_140_outer_finger.stl" />
        </geometry>
      </collision>
    </link>
    <gazebo reference="right_outer_finger">
      <material>Gazebo/Grey</material>
      <selfCollide>True</selfCollide>
    </gazebo>

<!-- OK -->
    <joint name="left_outer_knuckle_joint" type="revolute">
      <origin xyz="0 -0.030601 0.054905" rpy="2.29579632679 0 0" />
      <parent link="robotiq_arg2f_base_link" />
      <child link="left_outer_knuckle" />
      <axis xyz="-1 0 0" />
      <limit lower="-2" upper="2" velocity="2.0" effort="1000" />
    </joint>

<!-- OK -->
    <joint name="right_outer_knuckle_joint" type="revolute">
      <origin xyz="0 0.030601 0.054905" rpy="2.29579632679 0 3.14" />
      <parent link="robotiq_arg2f_base_link" />
      <child link="right_outer_knuckle" />
      <axis xyz="-1 0 0" />
      <limit lower="-2" upper="2" velocity="2.0" effort="1000" />
    </joint>

<!-- OK -->
    <joint name="left_inner_knuckle_joint" type="revolute">
      <origin xyz="0 -0.0127 0.06142" rpy="2.29579632679 0 0" />
      <parent link="robotiq_arg2f_base_link" />
      <child link="left_inner_knuckle" />
      <axis xyz="-1 0 0" />
      <limit lower="0" upper="0.8757" velocity="2.0" effort="1000" />
      <mimic joint="left_outer_knuckle_joint" multiplier="-1" offset="0" />
    </joint>

<!-- OK -->
    <joint name="right_inner_knuckle_joint" type="revolute">
      <origin xyz="0 0.0127 0.06142" rpy="2.29579632679 0  -3.14" />
      <parent link="robotiq_arg2f_base_link" />
      <child link="right_inner_knuckle" />
      <axis xyz="-1 0 0" />
      <limit lower="0" upper="0.8757" velocity="2.0" effort="1000" />
      <mimic joint="right_outer_knuckle_joint" multiplier="-1" offset="0" />
    </joint>

    <joint name="left_outer_finger_joint" type="revolute">
      <origin xyz="0 0.01821998610742 0.0260018192872234" rpy="0 0 0" />
      <parent link="left_outer_knuckle" />
      <child link="left_outer_finger" />
      <axis xyz="1 0 0" />
      <limit lower="-2" upper="2" velocity="2.0" effort="1000" />
    </joint>

    <joint name="right_outer_finger_joint" type="revolute">
      <origin xyz="0 0.01821998610742 0.0260018192872234" rpy="0 0 0" />
      <parent link="right_outer_knuckle" />
      <child link="right_outer_finger" />
      <axis xyz="-1 0 0" />
      <limit lower="-2" upper="2" velocity="2.0" effort="1000" />
    </joint>

    <joint name="left_inner_finger_joint" type="revolute">
      <origin xyz="0 0.0817554015893473 -0.0282203446692936" rpy="-.725 0 0" />
      <parent link="left_outer_finger" />
      <child link="left_inner_finger" />
      <axis xyz="1 0 0" />
      <limit lower="-0.875" upper="0.8757" velocity="2.0" effort="1000" />
    </joint>

    <joint name="right_inner_finger_joint" type="revolute">
      <origin xyz="0 0.0817554015893473 -0.0282203446692936" rpy="-.725 0 0" />
      <parent link="right_outer_finger" />
      <child link="right_inner_finger" />
      <axis xyz="1 0 0" />
      <limit lower="-0.875" upper="0.8757" velocity="2.0" effort="1000" />
    </joint>

    <gazebo>
      <joint name="left_inner_finger_knuckle_joint" type="revolute">
        <pose frame="">0 0.006 -0.018 0 0 0</pose>
        <parent>mara::left_inner_knuckle</parent>
        <child>mara::left_inner_finger</child>
        <axis>
          <xyz>0 1 0</xyz>
          <limit>
            <lower>-0.6</lower>
            <upper>0.6</upper>
            <velocity>2.0</velocity>
            <effort>1000</effort>
          </limit>
        </axis>
      </joint>

      <joint name="right_inner_finger_knuckle_joint" type="revolute">
        <pose frame="">0 0.006 -0.018 0 0 0</pose>
        <parent>mara::right_inner_knuckle</parent>
        <child>mara::right_inner_finger</child>
        <axis>
          <xyz>0 1 0</xyz>
          <limit>
            <lower>-0.6</lower>
            <upper>0.6</upper>
            <velocity>2.0</velocity>
            <effort>1000</effort>
          </limit>
        </axis>
      </joint>

      <plugin filename="librobotiq_140_gripper_gazebo_plugin.so" name="robotiq_arg2f_gazebo_plugins"/>
      <plugin filename="libgazebo_grasp_fix.so" name="gazebo_grasp_fix">
        <arm>
          <arm_name>robot</arm_name>
          <palm_link>left_inner_finger</palm_link>
          <gripper_link>left_inner_finger</gripper_link>
          <gripper_link>right_inner_finger</gripper_link>
          <gripper_link>left_inner_knuckle</gripper_link>
          <gripper_link>right_inner_knuckle</gripper_link>
        </arm>
        <forces_angle_tolerance>100</forces_angle_tolerance>
        <update_rate>20</update_rate>
        <grip_count_threshold>4</grip_count_threshold>
        <max_grip_count>8</max_grip_count>
        <release_tolerance>0.05</release_tolerance>
        <disable_collisions_on_attach>false</disable_collisions_on_attach>
        <contact_topic>__default_topic__</contact_topic>
     </plugin>
    </gazebo>

  </xacro:macro>
</robot>
