<?xml version="1.0" ?>
<!-- =================================================================================== -->
<!-- |    This document was autogenerated by xacro from /home/erle/ros2_crystal/src/mara/mara_description/urdf/mara_robot_camera_top.urdf.xacro | -->
<!-- |    EDITING THIS FILE BY HAND IS NOT RECOMMENDED                                 | -->
<!-- =================================================================================== -->
<robot name="mara" xmlns:xacro="http://ros.org/wiki/xacro">
  <!--
  Author: Alejandro  Hernandez
-->
  <!-- <xacro:include filename="$(find mara_description)/urdf/camera_top.urdf.xacro" /> -->
  <link name="base_link">
    <inertial>
      <origin rpy="0 0 0" xyz="8.625E-08 -4.6583E-06 0.03145"/>
      <mass value="7.033"/>
      <inertia ixx="0.1478344" ixy="-0.00001" ixz="0.0" iyy="0.14782335" iyz="0.0" izz="0.29471799"/>
    </inertial>
    <visual>
      <origin rpy="0 0 0" xyz="0 0 0"/>
      <geometry>
        <mesh filename="package://mara_description/meshes/Base_plancha.stl" scale="0.001 0.001 0.001"/>
      </geometry>
      <material name="Gazebo/Grey">
        <color rgba="0. 0. 0. 1"/>
      </material>
    </visual>
    <collision>
      <origin rpy="0 0 0" xyz="0 0 0"/>
      <geometry>
        <mesh filename="package://mara_description/meshes/Base_plancha.stl" scale="0.001 0.001 0.001"/>
      </geometry>
    </collision>
  </link>
  <gazebo reference="base_link">
    <material>Gazebo/Grey</material>
    <selfCollide>True</selfCollide>
  </gazebo>
  <link name="base_robot">
    <inertial>
      <origin rpy="0 0 0" xyz="8.625E-08 -4.6583E-06 0.03145"/>
      <mass value="7.033"/>
      <inertia ixx="0.1478344" ixy="-0.00001" ixz="0.0" iyy="0.14782335" iyz="0.0" izz="0.29471799"/>
    </inertial>
    <visual>
      <origin rpy="0 0 0" xyz="0 0 0"/>
      <geometry>
        <mesh filename="package://mara_description/meshes/Base.stl" scale="0.001 0.001 0.001"/>
      </geometry>
      <material name="Gazebo/Grey">
        <color rgba="0. 0. 0. 1"/>
      </material>
    </visual>
    <collision>
      <origin rpy="0 0 0" xyz="0 0 0"/>
      <geometry>
        <mesh filename="package://mara_description/meshes/Base.stl" scale="0.001 0.001 0.001"/>
      </geometry>
    </collision>
  </link>
  <gazebo reference="base_robot">
    <material>Gazebo/Grey</material>
    <selfCollide>True</selfCollide>
  </gazebo>
  <link name="motor1_link">
    <inertial>
      <origin rpy="0 0 0" xyz="8.625E-08 -4.6583E-06 0.03145"/>
      <mass value="7.033"/>
      <inertia ixx="0.1478344" ixy="-0.00001" ixz="0.0" iyy="0.14782335" iyz="0.0" izz="0.29471799"/>
    </inertial>
    <visual>
      <origin rpy="0 0 0" xyz="0 0 0"/>
      <geometry>
        <mesh filename="package://mara_description/meshes/MARA_T49.stl" scale="0.001 0.001 0.001"/>
      </geometry>
      <material name="Gazebo/White">
        <color rgba="0. 0. 0. 1"/>
      </material>
    </visual>
    <collision>
      <origin rpy="0 0 0" xyz="0 0 0"/>
      <geometry>
        <mesh filename="package://mara_description/meshes/MARA_T49.stl" scale="0.001 0.001 0.001"/>
      </geometry>
    </collision>
  </link>
  <gazebo reference="motor1_link">
    <material>Gazebo/White</material>
    <selfCollide>True</selfCollide>
  </gazebo>
  <link name="motor1_cover">
    <inertial>
      <origin rpy="0 0 0" xyz="8.625E-08 -4.6583E-06 0.03145"/>
      <mass value="7.033"/>
      <inertia ixx="0.1478344" ixy="-0.00001" ixz="0.0" iyy="0.14782335" iyz="0.0" izz="0.29471799"/>
    </inertial>
    <visual>
      <origin rpy="0 0 0" xyz="0 0 0"/>
      <geometry>
        <mesh filename="package://mara_description/meshes/MARA_T49_Black.stl" scale="0.001 0.001 0.001"/>
      </geometry>
      <material name="Gazebo/Black">
        <color rgba="0. 0. 0. 1"/>
      </material>
    </visual>
    <collision>
      <origin rpy="0 0 0" xyz="0 0 0"/>
      <geometry>
        <mesh filename="package://mara_description/meshes/MARA_T49_Black.stl" scale="0.001 0.001 0.001"/>
      </geometry>
    </collision>
  </link>
  <gazebo reference="motor1_cover">
    <material>Gazebo/Black</material>
    <selfCollide>True</selfCollide>
  </gazebo>
  <link name="motor2_link">
    <inertial>
      <origin rpy="0 0 0" xyz="8.625E-08 -4.6583E-06 0.03145"/>
      <mass value="7.033"/>
      <inertia ixx="0.1478344" ixy="-0.00001" ixz="0.0" iyy="0.14782335" iyz="0.0" izz="0.29471799"/>
    </inertial>
    <visual>
      <origin rpy="0 0 0" xyz="0 0 0"/>
      <geometry>
        <mesh filename="package://mara_description/meshes/MARA_Link1.stl" scale="0.001 0.001 0.001"/>
      </geometry>
      <material name="Gazebo/Black">
        <color rgba="0. 0. 0. 1"/>
      </material>
    </visual>
    <collision>
      <origin rpy="0 0 0" xyz="0 0 0"/>
      <geometry>
        <mesh filename="package://mara_description/meshes/MARA_Link1.stl" scale="0.001 0.001 0.001"/>
      </geometry>
    </collision>
  </link>
  <gazebo reference="motor2_link">
    <material>Gazebo/Black</material>
    <selfCollide>True</selfCollide>
  </gazebo>
  <link name="motor3_link">
    <inertial>
      <origin rpy="0 0 0" xyz="8.625E-08 -4.6583E-06 0.03145"/>
      <mass value="7.033"/>
      <inertia ixx="0.1478344" ixy="-0.00001" ixz="0.0" iyy="0.14782335" iyz="0.0" izz="0.29471799"/>
    </inertial>
    <visual>
      <origin rpy="0 0 0" xyz="0 0 0"/>
      <geometry>
        <mesh filename="package://mara_description/meshes/MARA_T30.stl" scale="0.001 0.001 0.001"/>
      </geometry>
      <material name="Gazebo/White">
        <color rgba="0. 0. 0. 1"/>
      </material>
    </visual>
    <collision>
      <origin rpy="0 0 0" xyz="0 0 0"/>
      <geometry>
        <mesh filename="package://mara_description/meshes/MARA_T30.stl" scale="0.001 0.001 0.001"/>
      </geometry>
    </collision>
  </link>
  <gazebo reference="motor3_link">
    <material>Gazebo/White</material>
    <selfCollide>True</selfCollide>
  </gazebo>
  <link name="motor3_cover">
    <inertial>
      <origin rpy="0 0 0" xyz="8.625E-08 -4.6583E-06 0.03145"/>
      <mass value="7.033"/>
      <inertia ixx="0.1478344" ixy="-0.00001" ixz="0.0" iyy="0.14782335" iyz="0.0" izz="0.29471799"/>
    </inertial>
    <visual>
      <origin rpy="0 0 0" xyz="0 0 0"/>
      <geometry>
        <mesh filename="package://mara_description/meshes/MARA_T30_Black.stl" scale="0.001 0.001 0.001"/>
      </geometry>
      <material name="Gazebo/Black">
        <color rgba="0. 0. 0. 1"/>
      </material>
    </visual>
    <collision>
      <origin rpy="0 0 0" xyz="0 0 0"/>
      <geometry>
        <mesh filename="package://mara_description/meshes/MARA_T30_Black.stl" scale="0.001 0.001 0.001"/>
      </geometry>
    </collision>
  </link>
  <gazebo reference="motor3_cover">
    <material>Gazebo/Black</material>
    <selfCollide>True</selfCollide>
  </gazebo>
  <link name="motor4_link">
    <inertial>
      <origin rpy="0 0 0" xyz="8.625E-08 -4.6583E-06 0.03145"/>
      <mass value="7.033"/>
      <inertia ixx="0.1478344" ixy="-0.00001" ixz="0.0" iyy="0.14782335" iyz="0.0" izz="0.29471799"/>
    </inertial>
    <visual>
      <origin rpy="0 0 0" xyz="0 0 0"/>
      <geometry>
        <mesh filename="package://mara_description/meshes/MARA_Link2.stl" scale="0.001 0.001 0.001"/>
      </geometry>
      <material name="Gazebo/Black">
        <color rgba="0. 0. 0. 1"/>
      </material>
    </visual>
    <collision>
      <origin rpy="0 0 0" xyz="0 0 0"/>
      <geometry>
        <mesh filename="package://mara_description/meshes/MARA_Link2.stl" scale="0.001 0.001 0.001"/>
      </geometry>
    </collision>
  </link>
  <gazebo reference="motor4_link">
    <material>Gazebo/Black</material>
    <selfCollide>True</selfCollide>
  </gazebo>
  <link name="motor5_link">
    <inertial>
      <origin rpy="0 0 0" xyz="8.625E-08 -4.6583E-06 0.03145"/>
      <mass value="7.033"/>
      <inertia ixx="0.1478344" ixy="-0.00001" ixz="0.0" iyy="0.14782335" iyz="0.0" izz="0.29471799"/>
    </inertial>
    <visual>
      <origin rpy="0 0 0" xyz="0 0 0"/>
      <geometry>
        <mesh filename="package://mara_description/meshes/MARA_T5.4.stl" scale="0.001 0.001 0.001"/>
      </geometry>
      <material name="Gazebo/White">
        <color rgba="0. 0. 0. 1"/>
      </material>
    </visual>
    <collision>
      <origin rpy="0 0 0" xyz="0 0 0"/>
      <geometry>
        <mesh filename="package://mara_description/meshes/MARA_T5.4.stl" scale="0.001 0.001 0.001"/>
      </geometry>
    </collision>
  </link>
  <gazebo reference="motor5_link">
    <material>Gazebo/White</material>
    <selfCollide>True</selfCollide>
  </gazebo>
  <link name="motor5_cover">
    <inertial>
      <origin rpy="0 0 0" xyz="8.625E-08 -4.6583E-06 0.03145"/>
      <mass value="7.033"/>
      <inertia ixx="0.1478344" ixy="-0.00001" ixz="0.0" iyy="0.14782335" iyz="0.0" izz="0.29471799"/>
    </inertial>
    <visual>
      <origin rpy="0 0 0" xyz="0 0 0"/>
      <geometry>
        <mesh filename="package://mara_description/meshes/MARA_T5.4_black.stl" scale="0.001 0.001 0.001"/>
      </geometry>
      <material name="Gazebo/Black">
        <color rgba="0. 0. 0. 1"/>
      </material>
    </visual>
    <collision>
      <origin rpy="0 0 0" xyz="0 0 0"/>
      <geometry>
        <mesh filename="package://mara_description/meshes/MARA_T5.4_black.stl" scale="0.001 0.001 0.001"/>
      </geometry>
    </collision>
  </link>
  <gazebo reference="motor5_cover">
    <material>Gazebo/Black</material>
    <selfCollide>True</selfCollide>
  </gazebo>
  <link name="motor6_link">
    <inertial>
      <origin rpy="0 0 0" xyz="8.625E-08 -4.6583E-06 0.03145"/>
      <mass value="7.033"/>
      <inertia ixx="0.1478344" ixy="-0.00001" ixz="0.0" iyy="0.14782335" iyz="0.0" izz="0.29471799"/>
    </inertial>
    <visual>
      <origin rpy="0 0 0" xyz="0 0 0"/>
      <geometry>
        <mesh filename="package://mara_description/meshes/MARA_GripperAdapter.stl" scale="0.001 0.001 0.001"/>
      </geometry>
      <material name="Gazebo/Black">
        <color rgba="0. 0. 0. 1"/>
      </material>
    </visual>
    <collision>
      <origin rpy="0 0 0" xyz="0 0 0"/>
      <geometry>
        <mesh filename="package://mara_description/meshes/MARA_GripperAdapter.stl" scale="0.001 0.001 0.001"/>
      </geometry>
    </collision>
  </link>
  <gazebo reference="motor6_link">
    <material>Gazebo/Black</material>
    <selfCollide>True</selfCollide>
  </gazebo>
  <link name="ee_link">
    </link>
  <gazebo reference="ee_link">
    <material>Gazebo/Blue</material>
    <selfCollide>False</selfCollide>
  </gazebo>
  <joint name="joint_bases" type="fixed">
    <origin rpy="0 0 0" xyz="0 0 0.04"/>
    <parent link="base_link"/>
    <child link="base_robot"/>
  </joint>
  <joint name="motor1" type="revolute">
    <origin rpy="0 0 0" xyz="0 0 0.05122"/>
    <parent link="base_robot"/>
    <child link="motor1_link"/>
    <axis xyz="0 0 -1"/>
    <limit effort="330.0" lower="-2.3562" upper="2.3562" velocity="3.1416"/>
    <dynamics damping="0" friction="0"/>
  </joint>
  <joint name="motor1_cover_joint" type="fixed">
    <origin rpy="0 0 0" xyz="0 0 0.0"/>
    <parent link="motor1_link"/>
    <child link="motor1_cover"/>
  </joint>
  <joint name="motor2" type="revolute">
    <origin rpy="0 0 0" xyz="0.118 0 0.1637"/>
    <parent link="motor1_link"/>
    <child link="motor2_link"/>
    <axis xyz="1 0 0"/>
    <limit effort="330.0" lower="-2.3562" upper="2.3562" velocity="3.1416"/>
    <dynamics damping="0" friction="0"/>
  </joint>
  <joint name="motor3" type="revolute">
    <origin rpy="0 0 0" xyz="-0.009 0 0.2"/>
    <parent link="motor2_link"/>
    <child link="motor3_link"/>
    <axis xyz="1 0 0"/>
    <limit effort="330.0" lower="-2.3562" upper="2.3562" velocity="3.1416"/>
    <dynamics damping="0" friction="0"/>
  </joint>
  <joint name="motor3_cover_joint" type="fixed">
    <origin rpy="0 0 0" xyz="0 0 0.0"/>
    <parent link="motor3_link"/>
    <child link="motor3_cover"/>
  </joint>
  <joint name="motor4" type="revolute">
    <origin rpy="0 0 0" xyz="-0.109255 0 0.149255"/>
    <parent link="motor3_link"/>
    <child link="motor4_link"/>
    <axis xyz="0 0 1"/>
    <limit effort="330.0" lower="-2.3562" upper="2.3562" velocity="3.1416"/>
    <dynamics damping="0" friction="0"/>
  </joint>
  <joint name="motor5" type="revolute">
    <origin rpy="0 0 0" xyz="0.1054570 0 0.16074"/>
    <parent link="motor4_link"/>
    <child link="motor5_link"/>
    <axis xyz="1 0 0"/>
    <limit effort="330.0" lower="-2.3562" upper="2.3562" velocity="3.1416"/>
    <dynamics damping="0" friction="0"/>
  </joint>
  <joint name="motor5_cover_joint" type="fixed">
    <origin rpy="0 0 0" xyz="0 0 0.0"/>
    <parent link="motor5_link"/>
    <child link="motor5_cover"/>
  </joint>
  <joint name="motor6" type="revolute">
    <origin rpy="0 0 0" xyz="-0.10625569 0 0.14675569"/>
    <parent link="motor5_link"/>
    <child link="motor6_link"/>
    <axis xyz="0 0 1"/>
    <limit effort="330.0" lower="-2.3562" upper="2.3562" velocity="3.1416"/>
    <dynamics damping="0" friction="0"/>
  </joint>
  <joint name="ee_link" type="fixed">
    <origin rpy="0 -1.57 0" xyz="0 0.0 0.24"/>
    <parent link="motor6_link"/>
    <child link="ee_link"/>
  </joint>
  <link name="tool0"/>
  <joint name="motor6_link-tool0_fixed_joint" type="fixed">
    <origin rpy="0 -1.57 0" xyz="0 0.0 0.24"/>
    <parent link="motor6_link"/>
    <child link="tool0"/>
  </joint>
  <transmission name="shoulder_pan_trans">
    <type>transmission_interface/SimpleTransmission</type>
    <joint name="motor1">
      <hardwareInterface>hardware_interface/PositionJointInterface</hardwareInterface>
    </joint>
    <actuator name="shoulder_pan_motor">
      <mechanicalReduction>1</mechanicalReduction>
    </actuator>
  </transmission>
  <transmission name="shoulder_lift_trans">
    <type>transmission_interface/SimpleTransmission</type>
    <joint name="motor2">
      <hardwareInterface>hardware_interface/PositionJointInterface</hardwareInterface>
    </joint>
    <actuator name="shoulder_lift_motor">
      <mechanicalReduction>1</mechanicalReduction>
    </actuator>
  </transmission>
  <transmission name="elbow_trans">
    <type>transmission_interface/SimpleTransmission</type>
    <joint name="motor3">
      <hardwareInterface>hardware_interface/PositionJointInterface</hardwareInterface>
    </joint>
    <actuator name="elbow_motor">
      <mechanicalReduction>1</mechanicalReduction>
    </actuator>
  </transmission>
  <transmission name="wrist_1_trans">
    <type>transmission_interface/SimpleTransmission</type>
    <joint name="motor4">
      <hardwareInterface>hardware_interface/PositionJointInterface</hardwareInterface>
    </joint>
    <actuator name="wrist_1_motor">
      <mechanicalReduction>1</mechanicalReduction>
    </actuator>
  </transmission>
  <transmission name="wrist_2_trans">
    <type>transmission_interface/SimpleTransmission</type>
    <joint name="motor5">
      <hardwareInterface>hardware_interface/PositionJointInterface</hardwareInterface>
    </joint>
    <actuator name="wrist_2_motor">
      <mechanicalReduction>1</mechanicalReduction>
    </actuator>
  </transmission>
  <transmission name="wrist_3_trans">
    <type>transmission_interface/SimpleTransmission</type>
    <joint name="motor6">
      <hardwareInterface>hardware_interface/PositionJointInterface</hardwareInterface>
    </joint>
    <actuator name="wrist_3_motor">
      <mechanicalReduction>1</mechanicalReduction>
    </actuator>
  </transmission>
  <gazebo>
    <plugin filename="libgazebo_ros_joint_state_publisher.so" name="mara_joint_state">
      <ros>
        <argument>~/out:=joint_states</argument>
      </ros>
      <update_rate>25</update_rate>
      <joint_name>motor1</joint_name>
      <joint_name>motor2</joint_name>
      <joint_name>motor3</joint_name>
      <joint_name>motor4</joint_name>
      <joint_name>motor5</joint_name>
      <joint_name>motor6</joint_name>
      <joint_name>left_inner_knuckle_joint</joint_name>
      <joint_name>left_outer_knuckle_joint</joint_name>
      <joint_name>left_outer_finger_joint</joint_name>
      <joint_name>left_inner_finger_joint</joint_name>
      <joint_name>right_inner_knuckle_joint</joint_name>
      <joint_name>right_outer_knuckle_joint</joint_name>
      <joint_name>right_outer_finger_joint</joint_name>
      <joint_name>right_inner_finger_joint</joint_name>
    </plugin>
    <plugin filename="libmara_gazebo_joint_plugin.so" name="hros_actuation_servomotor_000000000001">
      <ros/>
      <axis1>motor2</axis1>
      <axis2>motor1</axis2>
      <type>series14</type>
    </plugin>
    <plugin filename="libmara_gazebo_joint_plugin.so" name="hros_actuation_servomotor_000000000002">
      <ros/>
      <axis1>motor3</axis1>
      <axis2>motor4</axis2>
      <type>series17</type>
    </plugin>
    <plugin filename="libmara_gazebo_joint_plugin.so" name="hros_actuation_servomotor_000000000003">
      <ros/>
      <axis1>motor5</axis1>
      <axis2>motor6</axis2>
      <type>series20</type>
    </plugin>
  </gazebo>
  <link name="robotiq_arg2f_base_link">
    <inertial>
      <origin rpy="0 0 0" xyz="8.625E-08 -4.6583E-06 0.03145"/>
      <mass value="0.22652"/>
      <inertia ixx="0.00020005" ixy="0" ixz="0" iyy="0.00017832" iyz="0" izz="0.00013478"/>
    </inertial>
    <visual>
      <origin rpy="0 0 1.57" xyz="0 0 0"/>
      <geometry>
        <mesh filename="package://robotiq_140_gripper_description/meshes/GRIPPER_base_axis.stl" scale="0.001 0.001 0.001"/>
      </geometry>
      <material name="">
        <color rgba="0.1 0.1 0.1 1"/>
      </material>
    </visual>
    <collision>
      <origin rpy="0 0 1.57" xyz="0 0 0"/>
      <geometry>
        <mesh filename="package://robotiq_140_gripper_description/meshes/GRIPPER_base_axis.stl" scale="0.001 0.001 0.001"/>
      </geometry>
    </collision>
  </link>
  <gazebo reference="robotiq_arg2f_base_link">
    <material>Gazebo/Grey</material>
    <selfCollide>True</selfCollide>
  </gazebo>
  <link name="left_outer_knuckle">
    <inertial>
      <origin rpy="0 0 0" xyz="0 0 0"/>
      <mass value="0.00853198276973456"/>
      <inertia ixx="2.89328108496468E-06" ixy="0" ixz="0" iyy="1.86719750325683E-06" iyz="-1.21858577871576E-06" izz="1.21905238907251E-06"/>
    </inertial>
    <visual>
      <origin rpy="0 0 0" xyz="0 0 0"/>
      <geometry>
        <mesh filename="package://robotiq_140_gripper_description/meshes/robotiq_140_left_outer_knuckle.stl"/>
      </geometry>
      <material name="">
        <color rgba="0.792156862745098 0.819607843137255 0.933333333333333 1"/>
      </material>
    </visual>
    <collision>
      <origin rpy="0 0 0" xyz="0 0 0"/>
      <geometry>
        <mesh filename="package://robotiq_140_gripper_description/meshes/robotiq_140_left_outer_knuckle.stl"/>
      </geometry>
    </collision>
  </link>
  <gazebo reference="left_outer_knuckle">
    <material>Gazebo/Grey</material>
    <selfCollide>True</selfCollide>
  </gazebo>
  <link name="right_outer_knuckle">
    <inertial>
      <origin rpy="0 0 0" xyz="0 0 0"/>
      <mass value="0.00853198276973456"/>
      <inertia ixx="2.89328108496468E-06" ixy="0" ixz="0" iyy="1.86719750325683E-06" iyz="-1.21858577871576E-06" izz="1.21905238907251E-06"/>
    </inertial>
    <visual>
      <origin rpy="0 0 0" xyz="0 0 0"/>
      <geometry>
        <mesh filename="package://robotiq_140_gripper_description/meshes/robotiq_140_right_outer_knuckle.stl"/>
      </geometry>
      <material name="">
        <color rgba="0.792156862745098 0.819607843137255 0.933333333333333 1"/>
      </material>
    </visual>
    <collision>
      <origin rpy="0 0 0" xyz="0 0 0"/>
      <geometry>
        <mesh filename="package://robotiq_140_gripper_description/meshes/robotiq_140_right_outer_knuckle.stl"/>
      </geometry>
    </collision>
  </link>
  <gazebo reference="right_outer_knuckle">
    <material>Gazebo/Grey</material>
    <selfCollide>True</selfCollide>
  </gazebo>
  <link name="left_inner_knuckle">
    <inertial>
      <origin rpy="0 0 0" xyz="0.000123011831763771 0.0507850843201817 0.00103968640075166"/>
      <mass value="0.0271177346495152"/>
      <inertia ixx="2.61910379223783E-05" ixy="-2.43616858946494E-07" ixz="-6.37789906117123E-09" iyy="2.8270243746167E-06" iyz="-5.37200748039765E-07" izz="2.83695868220296E-05"/>
    </inertial>
    <visual>
      <origin rpy="0 0 0" xyz="0 0 0"/>
      <geometry>
        <mesh filename="package://robotiq_140_gripper_description/meshes/robotiq_140_left_inner_knuckle.stl"/>
      </geometry>
      <material name="">
        <color rgba="0.1 0.1 0.1 1"/>
      </material>
    </visual>
  </link>
  <gazebo reference="left_inner_knuckle">
    <material>Gazebo/Grey</material>
    <selfCollide>True</selfCollide>
  </gazebo>
  <link name="right_inner_knuckle">
    <inertial>
      <origin rpy="0 0 0" xyz="0.000123011831763771 0.0507850843201817 0.00103968640075166"/>
      <mass value="0.0271177346495152"/>
      <inertia ixx="2.61910379223783E-05" ixy="-2.43616858946494E-07" ixz="-6.37789906117123E-09" iyy="2.8270243746167E-06" iyz="-5.37200748039765E-07" izz="2.83695868220296E-05"/>
    </inertial>
    <visual>
      <origin rpy="0 0 0" xyz="0 0 0"/>
      <geometry>
        <mesh filename="package://robotiq_140_gripper_description/meshes/robotiq_140_right_inner_knuckle.stl"/>
      </geometry>
      <material name="">
        <color rgba="0.1 0.1 0.1 1"/>
      </material>
    </visual>
  </link>
  <gazebo reference="right_inner_knuckle">
    <material>Gazebo/Grey</material>
    <selfCollide>True</selfCollide>
  </gazebo>
  <link name="left_inner_finger">
    <inertial>
      <origin rpy="0 0 0" xyz="0.0 0.031506174 -0.017648840"/>
      <mass value="0.0104003125914103"/>
      <inertia ixx="6.06863499e-06" ixy="0" ixz="0" iyy="7.46305064e-07" iyz="0" izz="6.21796490e-06"/>
    </inertial>
    <visual>
      <origin rpy="0 0 0" xyz="0 0 0"/>
      <geometry>
        <mesh filename="package://robotiq_140_gripper_description/meshes/robotiq_140_left_inner_finger.stl" scale="0.001 0.001 0.001"/>
      </geometry>
      <material name="">
        <color rgba="0.1 0.1 0.1 1"/>
      </material>
    </visual>
    <collision>
      <origin rpy="0 0 0" xyz="0 0 0"/>
      <geometry>
        <mesh filename="package://robotiq_140_gripper_description/meshes/robotiq_140_left_inner_finger.stl" scale="0.001 0.001 0.001"/>
      </geometry>
    </collision>
  </link>
  <gazebo reference="left_inner_finger">
    <material>Gazebo/Grey</material>
    <selfCollide>True</selfCollide>
  </gazebo>
  <link name="right_inner_finger">
    <inertial>
      <origin rpy="0 0 0" xyz="0.0 0.031506174 -0.017648840"/>
      <mass value="0.0104003125914103"/>
      <inertia ixx="6.06863499e-06" ixy="0" ixz="0" iyy="7.46305064e-07" iyz="0" izz="6.21796490e-06"/>
    </inertial>
    <visual>
      <origin rpy="0 0 0" xyz="0 0 0"/>
      <geometry>
        <mesh filename="package://robotiq_140_gripper_description/meshes/robotiq_140_right_inner_finger.stl" scale="0.001 0.001 0.001"/>
      </geometry>
      <material name="">
        <color rgba="0.1 0.1 0.1 1"/>
      </material>
    </visual>
    <collision>
      <origin rpy="0 0 0" xyz="0 0 0"/>
      <geometry>
        <mesh filename="package://robotiq_140_gripper_description/meshes/robotiq_140_right_inner_finger.stl" scale="0.001 0.001 0.001"/>
      </geometry>
    </collision>
  </link>
  <gazebo reference="right_inner_finger">
    <material>Gazebo/Grey</material>
    <selfCollide>True</selfCollide>
  </gazebo>
  <link name="left_outer_finger">
    <inertial>
      <origin rpy="0 0 0" xyz="0.00030115855001899 0.0373907951953854 -0.0208027427000385"/>
      <mass value="0.022614240507152"/>
      <inertia ixx="1.52518312458174E-05" ixy="9.76583423954399E-10" ixz="-5.43838577022588E-10" iyy="6.17694243867776E-06" iyz="6.78636130740228E-06" izz="1.16494917907219E-05"/>
    </inertial>
    <visual>
      <origin rpy="0 0 0" xyz="0 0 0"/>
      <geometry>
        <mesh filename="package://robotiq_140_gripper_description/meshes/robotiq_140_left_outer_finger.stl"/>
      </geometry>
      <material name="">
        <color rgba="0.1 0.1 0.1 1"/>
      </material>
    </visual>
    <collision>
      <origin rpy="0 0 0" xyz="0 0 0"/>
      <geometry>
        <mesh filename="package://robotiq_140_gripper_description/meshes/robotiq_140_left_outer_finger.stl"/>
      </geometry>
    </collision>
  </link>
  <gazebo reference="left_outer_finger">
    <material>Gazebo/Grey</material>
    <selfCollide>True</selfCollide>
  </gazebo>
  <link name="right_outer_finger">
    <inertial>
      <origin rpy="0 0 0" xyz="0.00030115855001899 0.0373907951953854 -0.0208027427000385"/>
      <mass value="0.022614240507152"/>
      <inertia ixx="1.52518312458174E-05" ixy="9.76583423954399E-10" ixz="-5.43838577022588E-10" iyy="6.17694243867776E-06" iyz="6.78636130740228E-06" izz="1.16494917907219E-05"/>
    </inertial>
    <visual>
      <origin rpy="0 0 0" xyz="0 0 0"/>
      <geometry>
        <mesh filename="package://robotiq_140_gripper_description/meshes/robotiq_140_right_outer_finger.stl"/>
      </geometry>
      <material name="">
        <color rgba="0.1 0.1 0.1 1"/>
      </material>
    </visual>
    <collision>
      <origin rpy="0 0 0" xyz="0 0 0"/>
      <geometry>
        <mesh filename="package://robotiq_140_gripper_description/meshes/robotiq_140_right_outer_finger.stl"/>
      </geometry>
    </collision>
  </link>
  <gazebo reference="right_outer_finger">
    <material>Gazebo/Grey</material>
    <selfCollide>True</selfCollide>
  </gazebo>
  <joint name="left_outer_knuckle_joint" type="revolute">
    <origin rpy="2.31 0 0" xyz="0 -0.030601 0.054905"/>
    <parent link="robotiq_arg2f_base_link"/>
    <child link="left_outer_knuckle"/>
    <axis xyz="-1 0 0"/>
    <limit effort="1000" lower="0" upper="0.875" velocity="2.0"/>
  </joint>
  <joint name="right_outer_knuckle_joint" type="revolute">
    <origin rpy="2.31 0 3.14159265359" xyz="0 0.030601 0.054905"/>
    <parent link="robotiq_arg2f_base_link"/>
    <child link="right_outer_knuckle"/>
    <axis xyz="-1 0 0"/>
    <limit effort="1000" lower="0" upper="0.875" velocity="2.0"/>
  </joint>
  <joint name="left_inner_knuckle_joint" type="revolute">
    <origin rpy="2.29 0 0" xyz="0 -0.0127 0.06142"/>
    <parent link="robotiq_arg2f_base_link"/>
    <child link="left_inner_knuckle"/>
    <axis xyz="-1 0 0"/>
    <limit effort="1000" lower="0" upper="0.87" velocity="2.0"/>
  </joint>
  <joint name="right_inner_knuckle_joint" type="revolute">
    <origin rpy="2.29 0 -3.14159265359" xyz="0 0.0127 0.06142"/>
    <parent link="robotiq_arg2f_base_link"/>
    <child link="right_inner_knuckle"/>
    <axis xyz="-1 0 0"/>
    <limit effort="1000" lower="0" upper="0.87" velocity="2.0"/>
  </joint>
  <joint name="left_outer_finger_joint" type="revolute">
    <origin rpy="0 0 0" xyz="0 0.01821998610742 0.0260018192872234"/>
    <parent link="left_outer_knuckle"/>
    <child link="left_outer_finger"/>
    <axis xyz="-1 0 0"/>
    <limit effort="1000" lower="0.1" upper="0.875" velocity="2.0"/>
  </joint>
  <joint name="right_outer_finger_joint" type="revolute">
    <origin rpy="0 0 0" xyz="0 0.01821998610742 0.0260018192872234"/>
    <parent link="right_outer_knuckle"/>
    <child link="right_outer_finger"/>
    <axis xyz="-1 0 0"/>
    <limit effort="1000" lower="0.1" upper="0.875" velocity="2.0"/>
  </joint>
  <joint name="left_inner_finger_joint" type="revolute">
    <origin rpy="-.725 0 0" xyz="0 0.0817554015893473 -0.0282203446692936"/>
    <parent link="left_outer_finger"/>
    <child link="left_inner_finger"/>
    <axis xyz="1 0 0"/>
    <limit effort="1000" lower="-0.875" upper="0.8757" velocity="2.0"/>
  </joint>
  <joint name="right_inner_finger_joint" type="revolute">
    <origin rpy="-.725 0 0" xyz="0 0.0817554015893473 -0.0282203446692936"/>
    <parent link="right_outer_finger"/>
    <child link="right_inner_finger"/>
    <axis xyz="1 0 0"/>
    <limit effort="1000" lower="-0.875" upper="0.8757" velocity="2.0"/>
  </joint>
  <gazebo>
    <joint name="left_inner_finger_knuckle_joint" type="revolute">
      <pose frame="">0 0.006 -0.018 0 0 0</pose>
      <parent>mara::left_inner_knuckle</parent>
      <child>mara::left_inner_finger</child>
      <axis>
        <xyz>1 0 0</xyz>
        <limit>
          <lower>-0.8</lower>
          <upper>0.8</upper>
          <velocity>2.0</velocity>
          <effort>1000</effort>
        </limit>
      </axis>
    </joint>
    <joint name="right_inner_finger_knuckle_joint" type="revolute">
      <pose frame="">0 0.006 -0.018 0 0 0</pose>
      <parent>mara::right_inner_knuckle</parent>
      <child>mara::right_inner_finger</child>
      <axis>
        <xyz>-1 0 0</xyz>
        <limit>
          <lower>-0.8</lower>
          <upper>0.8</upper>
          <velocity>2.0</velocity>
          <effort>1000</effort>
        </limit>
      </axis>
    </joint>
    <plugin filename="librobotiq_140_gripper_gazebo_plugin.so" name="hros_actuation_gripper_000000000004"/>
  </gazebo>
  <link name="table">
    <contact>
      <lateral_friction value="1.0"/>
    </contact>
    <inertial>
      <origin rpy="0 0 0" xyz="0 0 0"/>
      <mass value="0.00001"/>
      <inertia ixx="0.001" ixy="0" ixz="0" iyy="0.001" iyz="0" izz="0.001"/>
    </inertial>
    <visual>
      <origin rpy="0 0 0" xyz="0 0 0.6"/>
      <geometry>
        <mesh filename="package://mara_description/urdf/table.obj" scale="1.5 1 0.05"/>
      </geometry>
      <material name="white">
        <color rgba="1 1 1 1"/>
      </material>
    </visual>
    <collision>
      <origin rpy="0 0 0" xyz="0 0 0.6"/>
      <geometry>
        <box size="1.5 1 0.05"/>
      </geometry>
    </collision>
    <visual>
      <origin rpy="0 0 0" xyz="-0.65 -0.4 0.29"/>
      <geometry>
        <mesh filename="package://mara_description/urdf/table.obj" scale="0.1 0.1 0.58"/>
      </geometry>
      <material name="framemat0"/>
    </visual>
    <visual>
      <origin rpy="0 0 0" xyz="-0.65 0.4 0.29"/>
      <geometry>
        <mesh filename="package://mara_description/urdf/table.obj" scale="0.1 0.1 0.58"/>
      </geometry>
      <material name="framemat0"/>
    </visual>
    <visual>
      <origin rpy="0 0 0" xyz="0.65 -0.4 0.29"/>
      <geometry>
        <mesh filename="package://mara_description/urdf/table.obj" scale="0.1 0.1 0.58"/>
      </geometry>
      <material name="framemat0"/>
    </visual>
    <visual>
      <origin rpy="0 0 0" xyz="0.65 0.4 0.29"/>
      <geometry>
        <mesh filename="package://mara_description/urdf/table.obj" scale="0.1 0.1 0.58"/>
      </geometry>
    </visual>
  </link>
  <link name="world"/>
  <joint name="end_effector_adapter_to_robotiq" type="fixed">
    <origin rpy="0 0 1.57" xyz=" 0 0 0.04659"/>
    <parent link="motor6_link"/>
    <child link="robotiq_arg2f_base_link"/>
  </joint>
  <joint name="world_to_table_joint" type="fixed">
    <origin rpy="0 0 0" xyz="0 0 0.02"/>
    <parent link="world"/>
    <child link="table"/>
  </joint>
  <joint name="table_to_base_joint" type="fixed">
    <origin rpy="0 0 0" xyz="0 0 0.62"/>
    <parent link="table"/>
    <child link="base_link"/>
  </joint>
</robot>
