<?xml version="1.0"?>
<robot xmlns:xacro="http://ros.org/wiki/xacro">

<!--
  Author: Alejandro  Hernandez
-->

  <xacro:include filename="$(find mara_description)/urdf/mara.transmission.xacro" />
  <xacro:include filename="$(find mara_description)/urdf/mara_gazebo.urdf.xacro" />

  <xacro:macro name="mara_robot"  params="prefix ee_link_distance MAC1 MAC2 MAC3">

    <link name="${prefix}base_link">
      <inertial>
        <origin rpy="0 0 0" xyz="8.625E-08 -4.6583E-06 0.03145"/>
        <mass value="7.033"/>
        <inertia ixx="0.1478344" ixy="-0.00001" ixz="0.0" iyy="0.14782335" iyz="0.0" izz="0.29471799"/>
      </inertial>
      <visual>
        <origin rpy="0 0 0" xyz="0 0 0"/>
        <geometry>
          <mesh filename="package://mara_description/meshes/Base_plancha.dae" scale="0.001 0.001 0.001"/>
        </geometry>
        <material name="Gazebo/Grey">
          <color rgba="0. 0. 0. 1"/>
        </material>
      </visual>
      <collision>
        <origin rpy="0 0 0" xyz="0 0 0"/>
        <geometry>
          <mesh filename="package://mara_description/meshes/Base_plancha.dae" scale="0.001 0.001 0.001"/>
        </geometry>
      </collision>
    </link>
    <gazebo reference="${prefix}base_link">
      <material>Gazebo/Grey</material>
      <selfCollide>True</selfCollide>
    </gazebo>

    <link name="${prefix}base_robot">
      <inertial>
        <origin rpy="0 0 0" xyz="8.625E-08 -4.6583E-06 0.03145"/>
        <mass value="7.033"/>
        <inertia ixx="0.1478344" ixy="0.00001" ixz="0.0" iyy="0.14782335" iyz="0.0" izz="0.29471799"/>
      </inertial>
      <visual>
        <origin rpy="0 0 0" xyz="0 0 0"/>
        <geometry>
          <mesh filename="package://mara_description/meshes/Base.dae" scale="0.001 0.001 0.001"/>
        </geometry>
        <material name="Gazebo/Black">
          <color rgba="1. 0. 0. 1.0"/>
        </material>
      </visual>
      <collision>
        <origin rpy="0 0 0" xyz="0 0 0"/>
        <geometry>
          <mesh filename="package://mara_description/meshes/Base.dae" scale="0.001 0.001 0.001"/>
        </geometry>
      </collision>
    </link>
    <gazebo reference="${prefix}base_robot">
      <material>Gazebo/Black</material>
      <selfCollide>True</selfCollide>
    </gazebo>

    <link name="${prefix}motor1_link">
      <inertial>
        <origin rpy="0 0 0" xyz="0.02066 0 0.12051"/>
        <mass value="5.6"/>
        <inertia ixx="0.0200769278" ixy="-7.72273E-006" ixz="-0.0050158708" iyy="0.0257088151" iyz="5.49229E-006" izz="0.0120821377"/>
      </inertial>
      <visual>
        <origin rpy="0 0 0" xyz="0 0 0"/>
        <geometry>
          <mesh filename="package://mara_description/meshes/MARA_T49.dae" scale="0.001 0.001 0.001"/>
        </geometry>
        <material name="Gazebo/White">
          <color rgba="0. 0. 0. 1"/>
        </material>
      </visual>
      <collision>
        <origin rpy="0 0 0" xyz="0 0 0"/>
        <geometry>
          <mesh filename="package://mara_description/meshes/MARA_T49.dae" scale="0.001 0.001 0.001"/>
        </geometry>
      </collision>
    </link>
    <gazebo reference="${prefix}motor1_link">
      <material>Gazebo/White</material>
      <selfCollide>True</selfCollide>
    </gazebo>

    <link name="${prefix}motor1_cover">
      <inertial>
        <origin rpy="0 0 0" xyz="0 0 0"/>
        <mass value="0.0"/>
        <inertia ixx="0.0" ixy="0.0" ixz="0.0" iyy="0.0" iyz="0.0" izz="0.0"/>
      </inertial>
      <visual>
        <origin rpy="0 0 0" xyz="0 0 0"/>
        <geometry>
          <mesh filename="package://mara_description/meshes/MARA_T49_Black.dae" scale="0.001 0.001 0.001"/>
        </geometry>
        <material name="Gazebo/Black">
          <color rgba="0. 0. 0. 1"/>
        </material>
      </visual>
      <collision>
        <origin rpy="0 0 0" xyz="0 0 0"/>
        <geometry>
          <mesh filename="package://mara_description/meshes/MARA_T49_Black.dae" scale="0.001 0.001 0.001"/>
        </geometry>
      </collision>
    </link>
    <gazebo reference="${prefix}motor1_cover">
      <material>Gazebo/Black</material>
      <selfCollide>True</selfCollide>
    </gazebo>

    <link name="${prefix}motor2_link">
      <inertial>
        <origin rpy="0 0 0" xyz="-0.01665 0.0 0.09639"/>
        <mass value="1.24"/>
        <inertia ixx="0.0079614839" ixy="0.000000037" ixz="0.0003203013" iyy="0.007135338" iyz="-0.000001062" izz="0.001111114"/>
      </inertial>
      <visual>
        <origin rpy="0 0 0" xyz="0 0 0"/>
        <geometry>
          <mesh filename="package://mara_description/meshes/MARA_Link1.dae" scale="0.001 0.001 0.001"/>
        </geometry>
        <material name="Gazebo/Black">
          <color rgba="0. 0. 0. 1"/>
        </material>
      </visual>
      <collision>
        <origin rpy="0 0 0" xyz="0 0 0"/>
        <geometry>
          <mesh filename="package://mara_description/meshes/MARA_Link1.dae" scale="0.001 0.001 0.001"/>
        </geometry>
      </collision>
    </link>
    <gazebo reference="${prefix}motor2_link">
      <material>Gazebo/Black</material>
      <selfCollide>True</selfCollide>
    </gazebo>

    <link name="${prefix}motor3_link">
      <inertial>
        <origin rpy="0 0 0" xyz="-0.08963 0 0.0403"/>
        <mass value="3.95"/>
        <inertia ixx="0.0115136615" ixy="-1.231046E-005" ixz="0.003148516" iyy="0.0149841676" iyz="-8.81378E-006" izz="0.0070387807"/>
      </inertial>
      <visual>
        <origin rpy="0 0 0" xyz="0 0 0"/>
        <geometry>
          <mesh filename="package://mara_description/meshes/MARA_T30.dae" scale="0.001 0.001 0.001"/>
        </geometry>
        <material name="Gazebo/White">
          <color rgba="0. 0. 0. 1"/>
        </material>
      </visual>
      <collision>
        <origin rpy="0 0 0" xyz="0 0 0"/>
        <geometry>
          <mesh filename="package://mara_description/meshes/MARA_T30.dae" scale="0.001 0.001 0.001"/>
        </geometry>
      </collision>
    </link>
    <gazebo reference="${prefix}motor3_link">
      <material>Gazebo/White</material>
      <selfCollide>True</selfCollide>
    </gazebo>

    <link name="${prefix}motor3_cover">
      <inertial>
        <origin rpy="0 0 0" xyz="0 0 0"/>
        <mass value="0.0"/>
        <inertia ixx="0.0" ixy="0.0" ixz="0.0" iyy="0.0" iyz="0.0" izz="0.0"/>
      </inertial>
      <visual>
        <origin rpy="0 0 0" xyz="0 0 0"/>
        <geometry>
          <mesh filename="package://mara_description/meshes/MARA_T30_Black.dae" scale="0.001 0.001 0.001"/>
        </geometry>
        <material name="Gazebo/Black">
          <color rgba="0. 0. 0. 1"/>
        </material>
      </visual>
      <collision>
        <origin rpy="0 0 0" xyz="0 0 0"/>
        <geometry>
          <mesh filename="package://mara_description/meshes/MARA_T30_Black.dae" scale="0.001 0.001 0.001"/>
        </geometry>
      </collision>
    </link>
    <gazebo reference="${prefix}motor3_cover">
      <material>Gazebo/Black</material>
      <selfCollide>True</selfCollide>
    </gazebo>

    <link name="${prefix}motor4_link">
      <inertial>
        <origin rpy="0 0 0" xyz="0.06357 0.0 0.05698"/>
        <mass value="1.26"/>
        <inertia ixx="0.005919676" ixy="0.000000923" ixz="-0.0022280208" iyy="0.0068807393" iyz="6.1373E-007" izz="0.00257485"/>
      </inertial>
      <visual>
        <origin rpy="0 0 0" xyz="0 0 0"/>
        <geometry>
          <mesh filename="package://mara_description/meshes/MARA_Link2.dae" scale="0.001 0.001 0.001"/>
        </geometry>
        <material name="Gazebo/Black">
          <color rgba="0. 0. 0. 1"/>
        </material>
      </visual>
      <collision>
        <origin rpy="0 0 0" xyz="0 0 0"/>
        <geometry>
          <mesh filename="package://mara_description/meshes/MARA_Link2.dae" scale="0.001 0.001 0.001"/>
        </geometry>
      </collision>
    </link>
    <gazebo reference="${prefix}motor4_link">
      <material>Gazebo/Black</material>
      <selfCollide>True</selfCollide>
    </gazebo>

    <link name="${prefix}motor5_link">
      <inertial>
        <origin rpy="0 0 0" xyz="-0.09105 0.0 0.03676"/>
        <mass value="2.85"/>
        <inertia ixx="0.0072829492" ixy="3.77994E-006" ixz="0.0015682105" iyy="0.0098263499" iyz="2.52745E-006" izz="0.0045615321"/>
      </inertial>
      <visual>
        <origin rpy="0 0 0" xyz="0 0 0"/>
        <geometry>
          <mesh filename="package://mara_description/meshes/MARA_T5.4.dae" scale="0.001 0.001 0.001"/>
        </geometry>
        <material name="Gazebo/White">
          <color rgba="0. 0. 0. 1"/>
        </material>
      </visual>
      <collision>
        <origin rpy="0 0 0" xyz="0 0 0"/>
        <geometry>
          <mesh filename="package://mara_description/meshes/MARA_T5.4.dae" scale="0.001 0.001 0.001"/>
        </geometry>
      </collision>
    </link>
    <gazebo reference="${prefix}motor5_link">
      <material>Gazebo/White</material>
      <selfCollide>True</selfCollide>
    </gazebo>

    <link name="${prefix}motor5_cover">
      <inertial>
        <origin rpy="0 0 0" xyz="0 0 0"/>
        <mass value="0.0"/>
        <inertia ixx="0.0" ixy="0.0" ixz="0.0" iyy="0.0" iyz="0.0" izz="0.0"/>
      </inertial>
      <visual>
        <origin rpy="0 0 0" xyz="0 0 0"/>
        <geometry>
          <mesh filename="package://mara_description/meshes/MARA_T5.4_black.dae" scale="0.001 0.001 0.001"/>
        </geometry>
        <material name="Gazebo/Black">
          <color rgba="0. 0. 0. 1"/>
        </material>
      </visual>
      <collision>
        <origin rpy="0 0 0" xyz="0 0 0"/>
        <geometry>
          <mesh filename="package://mara_description/meshes/MARA_T5.4_black.dae" scale="0.001 0.001 0.001"/>
        </geometry>
      </collision>
    </link>
    <gazebo reference="${prefix}motor5_cover">
      <material>Gazebo/Black</material>
      <selfCollide>True</selfCollide>
    </gazebo>

    <!-- dummy link with the required tags-->
    <link name="${prefix}motor6_link">
      <inertial>
        <origin rpy="0 0 0" xyz="0 0 0"/>
        <mass value="0.00001"/>
        <inertia ixx="0" ixy="0" ixz="0" iyy="0" iyz="0" izz="0"/>
      </inertial>
      <visual>
        <origin rpy="0 0 0" xyz="0 0 0"/>
        <geometry>
          <sphere radius="0"/>
        </geometry>
      </visual>
      <collision>
        <origin rpy="0 0 0" xyz="0 0 0"/>
        <geometry>
          <sphere radius="0"/>
        </geometry>
      </collision>
    </link>

    <link name="${prefix}ee_link"/>

    <joint name="${prefix}joint_bases" type="fixed">
      <origin rpy="0 0 0" xyz="0 0 0.04"/>
      <parent link="${prefix}base_link"/>
      <child link="${prefix}base_robot"/>
    </joint>

    <joint name="${prefix}motor1" type="revolute">
      <origin rpy="0 0 0" xyz="0 0 0.05122"/>
      <parent link="${prefix}base_robot"/>
      <child link="${prefix}motor1_link"/>
      <axis xyz="0 0 1"/>
      <limit effort="104.0" lower="-3.1416" upper="3.1416" velocity="1.57"/>
      <dynamics damping="0" friction="0"/>
    </joint>

    <joint name="${prefix}motor1_cover_joint" type="fixed">
      <origin rpy="0 0 0" xyz="0 0 0.0"/>
      <parent link="${prefix}motor1_link"/>
      <child link="${prefix}motor1_cover"/>
    </joint>

    <joint name="${prefix}motor2" type="revolute">
      <origin rpy="0 0 0" xyz="0.118 0 0.1637"/>
      <parent link="${prefix}motor1_link"/>
      <child link="${prefix}motor2_link"/>
      <axis xyz="1 0 0"/>
      <limit effort="104.0" lower="-2.35" upper="2.35" velocity="1.57"/>
      <dynamics damping="0" friction="0"/>
    </joint>

    <joint name="${prefix}motor3" type="revolute">
      <origin rpy="0 0 0" xyz="-0.009 0 0.2"/>
      <parent link="${prefix}motor2_link"/>
      <child link="${prefix}motor3_link"/>
      <axis xyz="-1 0 0"/>
      <limit effort="69" lower="-2.61" upper="2.61" velocity="1.57"/>
      <dynamics damping="0" friction="0"/>
    </joint>

    <joint name="${prefix}motor3_cover_joint" type="fixed">
      <origin rpy="0 0 0" xyz="0 0 0.0"/>
      <parent link="${prefix}motor3_link"/>
      <child link="${prefix}motor3_cover"/>
    </joint>

    <joint name="${prefix}motor4" type="revolute">
      <origin rpy="0 0 0" xyz="-0.109255 0 0.149255"/>
      <parent link="${prefix}motor3_link"/>
      <child link="${prefix}motor4_link"/>
      <axis xyz="0 0 1"/>
      <limit effort="69" lower="-3.14" upper="3.14" velocity="1.57"/>
      <dynamics damping="0" friction="0"/>
    </joint>

    <joint name="${prefix}motor5" type="revolute">
      <origin rpy="0 0 0" xyz="0.1054570 0 0.16074"/>
      <parent link="${prefix}motor4_link"/>
      <child link="${prefix}motor5_link"/>
      <axis xyz="-1 0 0"/>
      <limit effort="34" lower="-2.56" upper="2.56" velocity="1.57"/>
      <dynamics damping="0" friction="0"/>
    </joint>

    <joint name="${prefix}motor5_cover_joint" type="fixed">
      <origin rpy="0 0 0" xyz="0 0 0.0"/>
      <parent link="${prefix}motor5_link"/>
      <child link="${prefix}motor5_cover"/>
    </joint>

    <joint name="${prefix}motor6" type="revolute">
      <origin rpy="0 0 0" xyz="-0.10625569 0 0.14675569"/>
      <parent link="${prefix}motor5_link"/>
      <child link="${prefix}motor6_link"/>
      <axis xyz="0 0 1"/>
      <limit effort="34" lower="-3.14" upper="3.14" velocity="1.57"/>
      <dynamics damping="0" friction="0"/>
    </joint>

    <joint name="${prefix}ee_link" type="fixed">
      <origin rpy="0 -1.57 0" xyz="0 0.0 ${ee_link_distance}"/>
      <parent link="${prefix}motor6_link"/>
      <child link="${prefix}ee_link"/>
    </joint>

    <link name="${prefix}tool0"/>
    <joint name="${prefix}motor6_link-tool0_fixed_joint" type="fixed">
      <origin rpy="0 -1.57 0" xyz="0 0.0 ${ee_link_distance}"/>
      <parent link="${prefix}motor6_link"/>
      <child link="${prefix}tool0"/>
    </joint>

    <xacro:mara_transmission prefix="${prefix}"/>
    <xacro:mara_gazebo prefix="${prefix}" MAC1="${MAC1}" MAC2="${MAC2}" MAC3="${MAC3}"/>

  </xacro:macro>
</robot>
