<?xml version="1.0" ?>
<!-- =================================================================================== -->
<!-- |    This document was autogenerated by xacro from ros2_mara_ws/src/mara/mara_description/urdf/mara_robot_gripper_hande.urdf.xacro | -->
<!-- |    EDITING THIS FILE BY HAND IS NOT RECOMMENDED                                 | -->
<!-- =================================================================================== -->
<robot name="mara" xmlns:xacro="http://ros.org/wiki/xacro">
  <!--
  Author: Alejandro  Hernandez
-->
  <link name="base_link">
    <inertial>
      <origin rpy="0 0 0" xyz="8.625E-08 -4.6583E-06 0.03145"/>
      <mass value="7.033"/>
      <inertia ixx="0.1478344" ixy="-0.00001" ixz="0.0" iyy="0.14782335" iyz="0.0" izz="0.29471799"/>
    </inertial>
    <visual>
      <origin rpy="0 0 0" xyz="0 0 0"/>
      <geometry>
        <mesh filename="package://mara_description/meshes/Base_plancha.dae" scale="0.001 0.001 0.001"/>
      </geometry>
      <material name="Gazebo/Grey">
        <color rgba="0. 0. 0. 1"/>
      </material>
    </visual>
    <collision>
      <origin rpy="0 0 0" xyz="0 0 0"/>
      <geometry>
        <mesh filename="package://mara_description/meshes/Base_plancha.dae" scale="0.001 0.001 0.001"/>
      </geometry>
    </collision>
  </link>
  <gazebo reference="base_link">
    <material>Gazebo/Grey</material>
    <selfCollide>True</selfCollide>
  </gazebo>
  <link name="base_robot">
    <inertial>
      <origin rpy="0 0 0" xyz="8.625E-08 -4.6583E-06 0.03145"/>
      <mass value="7.033"/>
      <inertia ixx="0.1478344" ixy="0.00001" ixz="0.0" iyy="0.14782335" iyz="0.0" izz="0.29471799"/>
    </inertial>
    <visual>
      <origin rpy="0 0 0" xyz="0 0 0"/>
      <geometry>
        <mesh filename="package://mara_description/meshes/Base.dae" scale="0.001 0.001 0.001"/>
      </geometry>
      <material name="Gazebo/Black">
        <color rgba="1. 0. 0. 1.0"/>
      </material>
    </visual>
    <collision>
      <origin rpy="0 0 0" xyz="0 0 0"/>
      <geometry>
        <mesh filename="package://mara_description/meshes/Base.dae" scale="0.001 0.001 0.001"/>
      </geometry>
    </collision>
  </link>
  <gazebo reference="base_robot">
    <material>Gazebo/Black</material>
    <selfCollide>True</selfCollide>
  </gazebo>
  <link name="motor1_link">
    <inertial>
      <origin rpy="0 0 0" xyz="0.02066 0 0.12051"/>
      <mass value="5.6"/>
      <inertia ixx="0.0200769278" ixy="-7.72273E-006" ixz="-0.0050158708" iyy="0.0257088151" iyz="5.49229E-006" izz="0.0120821377"/>
    </inertial>
    <visual>
      <origin rpy="0 0 0" xyz="0 0 0"/>
      <geometry>
        <mesh filename="package://mara_description/meshes/MARA_T49.dae" scale="0.001 0.001 0.001"/>
      </geometry>
      <material name="Gazebo/White">
        <color rgba="0. 0. 0. 1"/>
      </material>
    </visual>
    <collision>
      <origin rpy="0 0 0" xyz="0 0 0"/>
      <geometry>
        <mesh filename="package://mara_description/meshes/MARA_T49.dae" scale="0.001 0.001 0.001"/>
      </geometry>
    </collision>
  </link>
  <gazebo reference="motor1_link">
    <material>Gazebo/White</material>
    <selfCollide>True</selfCollide>
  </gazebo>
  <link name="motor1_cover">
    <inertial>
      <origin rpy="0 0 0" xyz="0 0 0"/>
      <mass value="0.0"/>
      <inertia ixx="0.0" ixy="0.0" ixz="0.0" iyy="0.0" iyz="0.0" izz="0.0"/>
    </inertial>
    <visual>
      <origin rpy="0 0 0" xyz="0 0 0"/>
      <geometry>
        <mesh filename="package://mara_description/meshes/MARA_T49_Black.dae" scale="0.001 0.001 0.001"/>
      </geometry>
      <material name="Gazebo/Black">
        <color rgba="0. 0. 0. 1"/>
      </material>
    </visual>
    <collision>
      <origin rpy="0 0 0" xyz="0 0 0"/>
      <geometry>
        <mesh filename="package://mara_description/meshes/MARA_T49_Black.dae" scale="0.001 0.001 0.001"/>
      </geometry>
    </collision>
  </link>
  <gazebo reference="motor1_cover">
    <material>Gazebo/Black</material>
    <selfCollide>True</selfCollide>
  </gazebo>
  <link name="motor2_link">
    <inertial>
      <origin rpy="0 0 0" xyz="-0.01665 0.0 0.09639"/>
      <mass value="1.24"/>
      <inertia ixx="0.0079614839" ixy="0.000000037" ixz="0.0003203013" iyy="0.007135338" iyz="-0.000001062" izz="0.001111114"/>
    </inertial>
    <visual>
      <origin rpy="0 0 0" xyz="0 0 0"/>
      <geometry>
        <mesh filename="package://mara_description/meshes/MARA_Link1.dae" scale="0.001 0.001 0.001"/>
      </geometry>
      <material name="Gazebo/Black">
        <color rgba="0. 0. 0. 1"/>
      </material>
    </visual>
    <collision>
      <origin rpy="0 0 0" xyz="0 0 0"/>
      <geometry>
        <mesh filename="package://mara_description/meshes/MARA_Link1.dae" scale="0.001 0.001 0.001"/>
      </geometry>
    </collision>
  </link>
  <gazebo reference="motor2_link">
    <material>Gazebo/Black</material>
    <selfCollide>True</selfCollide>
  </gazebo>
  <link name="motor3_link">
    <inertial>
      <origin rpy="0 0 0" xyz="-0.08963 0 0.0403"/>
      <mass value="3.95"/>
      <inertia ixx="0.0115136615" ixy="-1.231046E-005" ixz="0.003148516" iyy="0.0149841676" iyz="-8.81378E-006" izz="0.0070387807"/>
    </inertial>
    <visual>
      <origin rpy="0 0 0" xyz="0 0 0"/>
      <geometry>
        <mesh filename="package://mara_description/meshes/MARA_T30.dae" scale="0.001 0.001 0.001"/>
      </geometry>
      <material name="Gazebo/White">
        <color rgba="0. 0. 0. 1"/>
      </material>
    </visual>
    <collision>
      <origin rpy="0 0 0" xyz="0 0 0"/>
      <geometry>
        <mesh filename="package://mara_description/meshes/MARA_T30.dae" scale="0.001 0.001 0.001"/>
      </geometry>
    </collision>
  </link>
  <gazebo reference="motor3_link">
    <material>Gazebo/White</material>
    <selfCollide>True</selfCollide>
  </gazebo>
  <link name="motor3_cover">
    <inertial>
      <origin rpy="0 0 0" xyz="0 0 0"/>
      <mass value="0.0"/>
      <inertia ixx="0.0" ixy="0.0" ixz="0.0" iyy="0.0" iyz="0.0" izz="0.0"/>
    </inertial>
    <visual>
      <origin rpy="0 0 0" xyz="0 0 0"/>
      <geometry>
        <mesh filename="package://mara_description/meshes/MARA_T30_Black.dae" scale="0.001 0.001 0.001"/>
      </geometry>
      <material name="Gazebo/Black">
        <color rgba="0. 0. 0. 1"/>
      </material>
    </visual>
    <collision>
      <origin rpy="0 0 0" xyz="0 0 0"/>
      <geometry>
        <mesh filename="package://mara_description/meshes/MARA_T30_Black.dae" scale="0.001 0.001 0.001"/>
      </geometry>
    </collision>
  </link>
  <gazebo reference="motor3_cover">
    <material>Gazebo/Black</material>
    <selfCollide>True</selfCollide>
  </gazebo>
  <link name="motor4_link">
    <inertial>
      <origin rpy="0 0 0" xyz="0.06357 0.0 0.05698"/>
      <mass value="1.26"/>
      <inertia ixx="0.005919676" ixy="0.000000923" ixz="-0.0022280208" iyy="0.0068807393" iyz="6.1373E-007" izz="0.00257485"/>
    </inertial>
    <visual>
      <origin rpy="0 0 0" xyz="0 0 0"/>
      <geometry>
        <mesh filename="package://mara_description/meshes/MARA_Link2.dae" scale="0.001 0.001 0.001"/>
      </geometry>
      <material name="Gazebo/Black">
        <color rgba="0. 0. 0. 1"/>
      </material>
    </visual>
    <collision>
      <origin rpy="0 0 0" xyz="0 0 0"/>
      <geometry>
        <mesh filename="package://mara_description/meshes/MARA_Link2.dae" scale="0.001 0.001 0.001"/>
      </geometry>
    </collision>
  </link>
  <gazebo reference="motor4_link">
    <material>Gazebo/Black</material>
    <selfCollide>True</selfCollide>
  </gazebo>
  <link name="motor5_link">
    <inertial>
      <origin rpy="0 0 0" xyz="-0.09105 0.0 0.03676"/>
      <mass value="2.85"/>
      <inertia ixx="0.0072829492" ixy="3.77994E-006" ixz="0.0015682105" iyy="0.0098263499" iyz="2.52745E-006" izz="0.0045615321"/>
    </inertial>
    <visual>
      <origin rpy="0 0 0" xyz="0 0 0"/>
      <geometry>
        <mesh filename="package://mara_description/meshes/MARA_T5.4.dae" scale="0.001 0.001 0.001"/>
      </geometry>
      <material name="Gazebo/White">
        <color rgba="0. 0. 0. 1"/>
      </material>
    </visual>
    <collision>
      <origin rpy="0 0 0" xyz="0 0 0"/>
      <geometry>
        <mesh filename="package://mara_description/meshes/MARA_T5.4.dae" scale="0.001 0.001 0.001"/>
      </geometry>
    </collision>
  </link>
  <gazebo reference="motor5_link">
    <material>Gazebo/White</material>
    <selfCollide>True</selfCollide>
  </gazebo>
  <link name="motor5_cover">
    <inertial>
      <origin rpy="0 0 0" xyz="0 0 0"/>
      <mass value="0.0"/>
      <inertia ixx="0.0" ixy="0.0" ixz="0.0" iyy="0.0" iyz="0.0" izz="0.0"/>
    </inertial>
    <visual>
      <origin rpy="0 0 0" xyz="0 0 0"/>
      <geometry>
        <mesh filename="package://mara_description/meshes/MARA_T5.4_black.dae" scale="0.001 0.001 0.001"/>
      </geometry>
      <material name="Gazebo/Black">
        <color rgba="0. 0. 0. 1"/>
      </material>
    </visual>
    <collision>
      <origin rpy="0 0 0" xyz="0 0 0"/>
      <geometry>
        <mesh filename="package://mara_description/meshes/MARA_T5.4_black.dae" scale="0.001 0.001 0.001"/>
      </geometry>
    </collision>
  </link>
  <gazebo reference="motor5_cover">
    <material>Gazebo/Black</material>
    <selfCollide>True</selfCollide>
  </gazebo>
  <!-- dummy link with the required tags-->
  <link name="motor6_link">
    <inertial>
      <origin rpy="0 0 0" xyz="0 0 0"/>
      <mass value="0.00001"/>
      <inertia ixx="0" ixy="0" ixz="0" iyy="0" iyz="0" izz="0"/>
    </inertial>
    <visual>
      <origin rpy="0 0 0" xyz="0 0 0"/>
      <geometry>
        <sphere radius="0"/>
      </geometry>
    </visual>
    <collision>
      <origin rpy="0 0 0" xyz="0 0 0"/>
      <geometry>
        <sphere radius="0"/>
      </geometry>
    </collision>
  </link>
  <link name="ee_link"/>
  <joint name="joint_bases" type="fixed">
    <origin rpy="0 0 0" xyz="0 0 0.04"/>
    <parent link="base_link"/>
    <child link="base_robot"/>
  </joint>
  <joint name="motor1" type="revolute">
    <origin rpy="0 0 0" xyz="0 0 0.05122"/>
    <parent link="base_robot"/>
    <child link="motor1_link"/>
    <axis xyz="0 0 1"/>
    <limit effort="104.0" lower="-3.1416" upper="3.1416" velocity="1.57"/>
    <dynamics damping="0" friction="0"/>
  </joint>
  <joint name="motor1_cover_joint" type="fixed">
    <origin rpy="0 0 0" xyz="0 0 0.0"/>
    <parent link="motor1_link"/>
    <child link="motor1_cover"/>
  </joint>
  <joint name="motor2" type="revolute">
    <origin rpy="0 0 0" xyz="0.118 0 0.1637"/>
    <parent link="motor1_link"/>
    <child link="motor2_link"/>
    <axis xyz="1 0 0"/>
    <limit effort="104.0" lower="-2.35" upper="2.35" velocity="1.57"/>
    <dynamics damping="0" friction="0"/>
  </joint>
  <joint name="motor3" type="revolute">
    <origin rpy="0 0 0" xyz="-0.009 0 0.2"/>
    <parent link="motor2_link"/>
    <child link="motor3_link"/>
    <axis xyz="-1 0 0"/>
    <limit effort="69" lower="-2.61" upper="2.61" velocity="1.57"/>
    <dynamics damping="0" friction="0"/>
  </joint>
  <joint name="motor3_cover_joint" type="fixed">
    <origin rpy="0 0 0" xyz="0 0 0.0"/>
    <parent link="motor3_link"/>
    <child link="motor3_cover"/>
  </joint>
  <joint name="motor4" type="revolute">
    <origin rpy="0 0 0" xyz="-0.109255 0 0.149255"/>
    <parent link="motor3_link"/>
    <child link="motor4_link"/>
    <axis xyz="0 0 1"/>
    <limit effort="69" lower="-3.14" upper="3.14" velocity="1.57"/>
    <dynamics damping="0" friction="0"/>
  </joint>
  <joint name="motor5" type="revolute">
    <origin rpy="0 0 0" xyz="0.1054570 0 0.16074"/>
    <parent link="motor4_link"/>
    <child link="motor5_link"/>
    <axis xyz="-1 0 0"/>
    <limit effort="34" lower="-2.56" upper="2.56" velocity="1.57"/>
    <dynamics damping="0" friction="0"/>
  </joint>
  <joint name="motor5_cover_joint" type="fixed">
    <origin rpy="0 0 0" xyz="0 0 0.0"/>
    <parent link="motor5_link"/>
    <child link="motor5_cover"/>
  </joint>
  <joint name="motor6" type="revolute">
    <origin rpy="0 0 0" xyz="-0.10625569 0 0.14675569"/>
    <parent link="motor5_link"/>
    <child link="motor6_link"/>
    <axis xyz="0 0 1"/>
    <limit effort="34" lower="-3.14" upper="3.14" velocity="1.57"/>
    <dynamics damping="0" friction="0"/>
  </joint>
  <joint name="ee_link" type="fixed">
    <origin rpy="0 -1.57 0" xyz="0 0.0 0.18253"/>
    <parent link="motor6_link"/>
    <child link="ee_link"/>
  </joint>
  <link name="tool0"/>
  <joint name="motor6_link-tool0_fixed_joint" type="fixed">
    <origin rpy="0 -1.57 0" xyz="0 0.0 0.18253"/>
    <parent link="motor6_link"/>
    <child link="tool0"/>
  </joint>
  <transmission name="shoulder_pan_trans">
    <type>transmission_interface/SimpleTransmission</type>
    <joint name="motor1">
      <hardwareInterface>hardware_interface/PositionJointInterface</hardwareInterface>
    </joint>
    <actuator name="shoulder_pan_motor">
      <mechanicalReduction>1</mechanicalReduction>
    </actuator>
  </transmission>
  <transmission name="shoulder_lift_trans">
    <type>transmission_interface/SimpleTransmission</type>
    <joint name="motor2">
      <hardwareInterface>hardware_interface/PositionJointInterface</hardwareInterface>
    </joint>
    <actuator name="shoulder_lift_motor">
      <mechanicalReduction>1</mechanicalReduction>
    </actuator>
  </transmission>
  <transmission name="elbow_trans">
    <type>transmission_interface/SimpleTransmission</type>
    <joint name="motor3">
      <hardwareInterface>hardware_interface/PositionJointInterface</hardwareInterface>
    </joint>
    <actuator name="elbow_motor">
      <mechanicalReduction>1</mechanicalReduction>
    </actuator>
  </transmission>
  <transmission name="wrist_1_trans">
    <type>transmission_interface/SimpleTransmission</type>
    <joint name="motor4">
      <hardwareInterface>hardware_interface/PositionJointInterface</hardwareInterface>
    </joint>
    <actuator name="wrist_1_motor">
      <mechanicalReduction>1</mechanicalReduction>
    </actuator>
  </transmission>
  <transmission name="wrist_2_trans">
    <type>transmission_interface/SimpleTransmission</type>
    <joint name="motor5">
      <hardwareInterface>hardware_interface/PositionJointInterface</hardwareInterface>
    </joint>
    <actuator name="wrist_2_motor">
      <mechanicalReduction>1</mechanicalReduction>
    </actuator>
  </transmission>
  <transmission name="wrist_3_trans">
    <type>transmission_interface/SimpleTransmission</type>
    <joint name="motor6">
      <hardwareInterface>hardware_interface/PositionJointInterface</hardwareInterface>
    </joint>
    <actuator name="wrist_3_motor">
      <mechanicalReduction>1</mechanicalReduction>
    </actuator>
  </transmission>
  <gazebo>
    <plugin filename="libgazebo_ros_joint_state_publisher.so" name="joint_state">
      <ros>
        <argument>~/out:=joint_states</argument>
      </ros>
      <update_rate>25</update_rate>
      <joint_name>motor1</joint_name>
      <joint_name>motor2</joint_name>
      <joint_name>motor3</joint_name>
      <joint_name>motor4</joint_name>
      <joint_name>motor5</joint_name>
      <joint_name>motor6</joint_name>
      <joint_name>joint_finger</joint_name>
    </plugin>
    <plugin filename="libmara_gazebo_joint_plugin.so" name="hrim_actuator_rotaryservo_000000000001">
      <ros/>
      <axis1>motor2</axis1>
      <axis2>motor1</axis2>
      <type>series14</type>
    </plugin>
    <plugin filename="libmara_gazebo_joint_plugin.so" name="hrim_actuator_rotaryservo_000000000002">
      <ros/>
      <axis1>motor3</axis1>
      <axis2>motor4</axis2>
      <type>series17</type>
    </plugin>
    <plugin filename="libmara_gazebo_joint_plugin.so" name="hrim_actuator_rotaryservo_000000000003">
      <ros/>
      <axis1>motor5</axis1>
      <axis2>motor6</axis2>
      <type>series20</type>
    </plugin>
  </gazebo>
  <link name="robotiq_hande_base_link">
    <inertial>
      <origin rpy="0 0 0" xyz="0 0 0.04607"/>
      <mass value="0.86387"/>
      <inertia ixx="1017560E-9" ixy="0" ixz="2235E-9" iyy="1028041E-9" iyz="0" izz="489810E-9"/>
    </inertial>
    <visual>
      <origin rpy="0 0 0" xyz="0 0 0"/>
      <geometry>
        <mesh filename="package://robotiq_hande_gripper_description/meshes/hand-e.dae" scale="0.001 0.001 0.001"/>
      </geometry>
      <material name="Gazebo/Black">
        <color rgba="0.1 0.1 0.1 1"/>
      </material>
    </visual>
    <collision>
      <origin rpy="0 0 0" xyz="0 0 0"/>
      <geometry>
        <mesh filename="package://robotiq_hande_gripper_description/meshes/hand-e.dae" scale="0.001 0.001 0.001"/>
      </geometry>
    </collision>
  </link>
  <gazebo reference="robotiq_hande_base_link">
    <material>Gazebo/Black</material>
    <selfCollide>True</selfCollide>
  </gazebo>
  <link name="left_finger">
    <inertial>
      <origin rpy="0 0 0" xyz="0.02262 -0.00759 0.00738"/>
      <mass value="0.03804"/>
      <inertia ixx="13567E-9" ixy="1849E-9" ixz="3622E-9" iyy="15784E-9" iyz="3616E-9" izz="7478E-9"/>
    </inertial>
    <visual>
      <origin rpy="0 0 0" xyz="0 0 0"/>
      <geometry>
        <mesh filename="package://robotiq_hande_gripper_description/meshes/finger_1.dae" scale="0.001 0.001 0.001"/>
      </geometry>
      <material name="Gazebo/Grey">
        <color rgba="0.1 0.1 0.1 1"/>
      </material>
    </visual>
    <collision>
      <origin rpy="0 0 0" xyz="0 0 0"/>
      <geometry>
        <mesh filename="package://robotiq_hande_gripper_description/meshes/finger_1.dae" scale="0.001 0.001 0.001"/>
      </geometry>
    </collision>
  </link>
  <gazebo reference="left_finger">
    <material>Gazebo/Grey</material>
    <selfCollide>True</selfCollide>
  </gazebo>
  <link name="right_finger">
    <inertial>
      <origin rpy="0 0 0" xyz="-0.02262 0.00759 0.00738"/>
      <mass value="0.03804"/>
      <inertia ixx="13567E-9" ixy="1849E-9" ixz="-3622E-9" iyy="15784E-9" iyz="-3616E-9" izz="7478E-9"/>
    </inertial>
    <visual>
      <origin rpy="0 0 0" xyz="0 0 0"/>
      <geometry>
        <mesh filename="package://robotiq_hande_gripper_description/meshes/finger_2.dae" scale="0.001 0.001 0.001"/>
      </geometry>
      <material name="Gazebo/Grey">
        <color rgba="0.1 0.1 0.1 1"/>
      </material>
    </visual>
    <collision>
      <origin rpy="0 0 0" xyz="0 0 0"/>
      <geometry>
        <mesh filename="package://robotiq_hande_gripper_description/meshes/finger_2.dae" scale="0.001 0.001 0.001"/>
      </geometry>
    </collision>
  </link>
  <gazebo reference="right_finger">
    <material>Gazebo/Grey</material>
    <selfCollide>True</selfCollide>
  </gazebo>
  <joint name="joint_finger" type="prismatic">
    <origin rpy="0 0 0" xyz="0 0 0.099"/>
    <parent link="robotiq_hande_base_link"/>
    <child link="left_finger"/>
    <axis xyz="-1 0 0"/>
    <limit effort="130" lower="0" upper="0.025" velocity="0.15"/>
  </joint>
  <joint name="robotiq_hande_base_to_right_finger" type="prismatic">
    <origin rpy="0 0 0" xyz="0 0 0.099"/>
    <parent link="robotiq_hande_base_link"/>
    <child link="right_finger"/>
    <axis xyz="1 0 0"/>
    <limit effort="130" lower="0" upper="0.025" velocity="0.15"/>
    <mimic joint="joint_finger" multiplier="1" offset="0"/>
  </joint>
  <gazebo>
    <plugin filename="librobotiq_gripper_gazebo_plugin.so" name="hrim_actuator_gripper_000000000004">
      <kp>500</kp>
      <ki>3</ki>
      <kd>9</kd>
      <min_velocity>20</min_velocity>
      <max_velocity>150</max_velocity>
      <joint>joint_finger</joint>
      <joint>robotiq_hande_base_to_right_finger</joint>
    </plugin>
  </gazebo>
  <link name="table">
    <contact>
      <lateral_friction value="1.0"/>
    </contact>
    <inertial>
      <origin rpy="0 0 0" xyz="0 0 0"/>
      <mass value="0.00001"/>
      <inertia ixx="0.001" ixy="0" ixz="0" iyy="0.001" iyz="0" izz="0.001"/>
    </inertial>
    <visual>
      <origin rpy="0 0 0" xyz="0 0 0.6"/>
      <geometry>
        <mesh filename="package://mara_description/urdf/table.obj" scale="1.5 1 0.05"/>
      </geometry>
      <material name="brown">
        <color rgba="0.63 0.16 0.16 1"/>
      </material>
    </visual>
    <collision>
      <origin rpy="0 0 0" xyz="0 0 0.6"/>
      <geometry>
        <box size="1.5 1 0.05"/>
      </geometry>
    </collision>
    <visual>
      <origin rpy="0 0 0" xyz="-0.65 -0.4 0.29"/>
      <geometry>
        <mesh filename="package://mara_description/urdf/table.obj" scale="0.1 0.1 0.58"/>
      </geometry>
      <material name="framemat0"/>
    </visual>
    <visual>
      <origin rpy="0 0 0" xyz="-0.65 0.4 0.29"/>
      <geometry>
        <mesh filename="package://mara_description/urdf/table.obj" scale="0.1 0.1 0.58"/>
      </geometry>
      <material name="framemat0"/>
    </visual>
    <visual>
      <origin rpy="0 0 0" xyz="0.65 -0.4 0.29"/>
      <geometry>
        <mesh filename="package://mara_description/urdf/table.obj" scale="0.1 0.1 0.58"/>
      </geometry>
      <material name="framemat0"/>
    </visual>
    <visual>
      <origin rpy="0 0 0" xyz="0.65 0.4 0.29"/>
      <geometry>
        <mesh filename="package://mara_description/urdf/table.obj" scale="0.1 0.1 0.58"/>
      </geometry>
    </visual>
  </link>
  <gazebo reference="table">
    <material>Gazebo/Brown</material>
    <selfCollide>True</selfCollide>
  </gazebo>
  <link name="world"/>
  <link name="gripper_adapter">
    <inertial>
      <origin rpy="0 0 0" xyz="0 0 0.0173"/>
      <mass value="0.14"/>
      <inertia ixx="0.0001" ixy="0" ixz="0" iyy="0.0001" iyz="0" izz="0.0002"/>
    </inertial>
    <visual>
      <origin rpy="0 0 0" xyz="0 0 0"/>
      <geometry>
        <mesh filename="package://mara_description/meshes/gripper_adapter.dae" scale="0.001 0.001 0.001"/>
      </geometry>
      <material name="Gazebo/Wood">
        <color rgba="0. 0. 0. 1"/>
      </material>
    </visual>
    <collision>
      <origin rpy="0 0 0" xyz="0 0 0"/>
      <geometry>
        <mesh filename="package://mara_description/meshes/gripper_adapter.dae" scale="0.001 0.001 0.001"/>
      </geometry>
    </collision>
  </link>
  <gazebo reference="gripper_adapter">
    <material>Gazebo/Black</material>
    <selfCollide>True</selfCollide>
  </gazebo>
  <link name="robotiq_adapter_link">
    <inertial>
      <origin rpy="0 0 0" xyz="0 0 -0.0253"/>
      <mass value="0.317"/>
      <inertia ixx="298526E-9" ixy="3928E-9" ixz="-926E-9" iyy="354661E-9" iyz="42E-9" izz="415572E-9"/>
    </inertial>
    <visual>
      <origin rpy="0 0 0" xyz="0 0 0"/>
      <geometry>
        <mesh filename="package://mara_description/meshes/robotiq_adapter.dae" scale="0.001 0.001 0.001"/>
      </geometry>
      <material name="Gazebo/Black">
        <color rgba="0.0 0.0 0.0 1"/>
      </material>
    </visual>
    <collision>
      <origin rpy="0 0 0" xyz="0 0 0"/>
      <geometry>
        <mesh filename="package://mara_description/meshes/robotiq_adapter.dae" scale="0.001 0.001 0.001"/>
      </geometry>
    </collision>
  </link>
  <gazebo reference="robotiq_adapter_link">
    <material>Gazebo/Black</material>
    <selfCollide>True</selfCollide>
  </gazebo>
  <joint name="world_to_table_joint" type="fixed">
    <origin rpy="0 0 0" xyz="0 0 0.02"/>
    <parent link="world"/>
    <child link="table"/>
  </joint>
  <joint name="table_to_base_joint" type="fixed">
    <origin rpy="0 0 0" xyz="0 0 0.62"/>
    <parent link="table"/>
    <child link="base_link"/>
  </joint>
  <joint name="motor6_to_gripper_adapter" type="fixed">
    <origin rpy="0 0 0" xyz=" 0 0 -0.02026"/>
    <parent link="motor6_link"/>
    <child link="gripper_adapter"/>
  </joint>
  <joint name="gripper_adapter_to_robotiq_adapter" type="fixed">
    <origin rpy="0 0 0" xyz=" 0 0 0.05679"/>
    <parent link="gripper_adapter"/>
    <child link="robotiq_adapter_link"/>
  </joint>
  <joint name="robotiq_adapter_to_hande_base" type="fixed">
    <origin rpy="0 0 0" xyz=" 0 0 0"/>
    <parent link="robotiq_adapter_link"/>
    <child link="robotiq_hande_base_link"/>
  </joint>
</robot>
