<?xml version="1.0"?>
<robot xmlns:xacro="http://ros.org/wiki/xacro">

<!--
  Author: Alejandro  Hernandez
-->

  <xacro:include filename="$(find mara_description)/urdf/mara.transmission.xacro" />
  <xacro:include filename="$(find mara_description)/urdf/mara_gazebo.urdf.xacro" />

  <xacro:macro name="mara_robot"  params="prefix ee_link_distance">

    <link name="${prefix}base_link">
      <inertial>
        <origin rpy="0 0 0" xyz="8.625E-08 -4.6583E-06 0.03145"/>
        <mass value="7.033"/>
        <inertia ixx="0.1478344" ixy="-0.00001" ixz="0.0" iyy="0.14782335" iyz="0.0" izz="0.29471799"/>
      </inertial>
      <visual>
        <origin rpy="0 0 0" xyz="0 0 0"/>
        <geometry>
          <mesh filename="package://mara_description/meshes/Base_plancha.dae" scale="0.001 0.001 0.001"/>
        </geometry>
        <material name="Gazebo/Grey">
          <color rgba="0. 0. 0. 1"/>
        </material>
      </visual>
      <collision>
        <origin rpy="0 0 0" xyz="0 0 0"/>
        <geometry>
          <mesh filename="package://mara_description/meshes/Base_plancha.dae" scale="0.001 0.001 0.001"/>
        </geometry>
      </collision>
    </link>
    <gazebo reference="${prefix}base_link">
      <material>Gazebo/Grey</material>
      <selfCollide>True</selfCollide>
    </gazebo>

    <link name="${prefix}base_robot">
      <inertial>
        <origin rpy="0 0 0" xyz="8.625E-08 -4.6583E-06 0.03145"/>
        <mass value="7.033"/>
        <inertia ixx="0.1478344" ixy="-0.00001" ixz="0.0" iyy="0.14782335" iyz="0.0" izz="0.29471799"/>
      </inertial>
      <visual>
        <origin rpy="0 0 0" xyz="0 0 0"/>
        <geometry>
          <mesh filename="package://mara_description/meshes/Base.dae" scale="0.001 0.001 0.001"/>
        </geometry>
        <material name="Gazebo/Black">
          <color rgba="0. 0. 0. 1"/>
      </material>
      </visual>
      <collision>
        <origin rpy="0 0 0" xyz="0 0 0"/>
        <geometry>
          <mesh filename="package://mara_description/meshes/Base.dae" scale="0.001 0.001 0.001"/>
        </geometry>
      </collision>
    </link>
    <gazebo reference="${prefix}base_robot">
      <material>Gazebo/Black</material>
      <selfCollide>True</selfCollide>
    </gazebo>

    <link name="${prefix}motor1_link">
      <inertial>
        <origin rpy="0 0 0" xyz="8.625E-08 -4.6583E-06 0.03145"/>
        <mass value="5.8"/>
        <inertia ixx="0.10105893" ixy="0.000211" ixz="-0.004" iyy="0.09386624" iyz="-0.01698537" izz="0.01449937"/>
      </inertial>
      <visual>
        <origin rpy="0 0 0" xyz="0 0 0"/>
        <geometry>
          <mesh filename="package://mara_description/meshes/MARA_T49.dae" scale="0.001 0.001 0.001"/>
        </geometry>
        <material name="Gazebo/White">
          <color rgba="0. 0. 0. 1"/>
        </material>
      </visual>
      <collision>
        <origin rpy="0 0 0" xyz="0 0 0"/>
        <geometry>
          <mesh filename="package://mara_description/meshes/MARA_T49.dae" scale="0.001 0.001 0.001"/>
        </geometry>
      </collision>
    </link>
    <gazebo reference="${prefix}motor1_link">
      <material>Gazebo/White</material>
      <selfCollide>True</selfCollide>
    </gazebo>

    <link name="${prefix}motor1_cover">
      <inertial>
        <origin rpy="0 0 0" xyz="8.625E-08 -4.6583E-06 0.03145"/>
        <mass value="5.8"/>
        <inertia ixx="0.10105893" ixy="0.000211" ixz="-0.004" iyy="0.09386624" iyz="-0.01698537" izz="0.01449937"/>
      </inertial>
      <visual>
        <origin rpy="0 0 0" xyz="0 0 0"/>
        <geometry>
          <mesh filename="package://mara_description/meshes/MARA_T49_Black.dae" scale="0.001 0.001 0.001"/>
        </geometry>
        <material name="Gazebo/Black">
          <color rgba="0. 0. 0. 1"/>
        </material>
      </visual>
      <collision>
        <origin rpy="0 0 0" xyz="0 0 0"/>
        <geometry>
          <mesh filename="package://mara_description/meshes/MARA_T49_Black.dae" scale="0.001 0.001 0.001"/>
        </geometry>
      </collision>
    </link>
    <gazebo reference="${prefix}motor1_cover">
      <material>Gazebo/Black</material>
      <selfCollide>True</selfCollide>
    </gazebo>

    <link name="${prefix}motor2_link">
      <inertial>
        <origin rpy="0 0 0" xyz="8.625E-08 -4.6583E-06 0.03145"/>
        <mass value="1.03237"/>
        <inertia ixx="0.014865226" ixy="0.0" ixz="0.0" iyy="0.01557" iyz="0.00071" izz="0.00092"/>
      </inertial>
      <visual>
        <origin rpy="0 0 0" xyz="0 0 0"/>
        <geometry>
          <mesh filename="package://mara_description/meshes/MARA_Link1.dae" scale="0.001 0.001 0.001"/>
        </geometry>
        <material name="Gazebo/Black">
          <color rgba="0. 0. 0. 1"/>
        </material>
      </visual>
      <collision>
        <origin rpy="0 0 0" xyz="0 0 0"/>
        <geometry>
          <mesh filename="package://mara_description/meshes/MARA_Link1.dae" scale="0.001 0.001 0.001"/>
        </geometry>
      </collision>
    </link>
    <gazebo reference="${prefix}motor2_link">
      <material>Gazebo/Black</material>
      <selfCollide>True</selfCollide>
    </gazebo>

    <link name="${prefix}motor3_link">
      <inertial>
        <origin rpy="0 0 0" xyz="8.625E-08 -4.6583E-06 0.03145"/>
        <mass value="3.8"/>
        <inertia ixx="0.04517" ixy="0.00002" ixz="0.0" iyy="0.01587" iyz="0.01444" izz="0.03303"/>
      </inertial>
      <visual>
        <origin rpy="0 0 0" xyz="0 0 0"/>
        <geometry>
          <mesh filename="package://mara_description/meshes/MARA_T30.dae" scale="0.001 0.001 0.001"/>
        </geometry>
        <material name="Gazebo/White">
          <color rgba="0. 0. 0. 1"/>
        </material>
      </visual>
      <collision>
        <origin rpy="0 0 0" xyz="0 0 0"/>
        <geometry>
          <mesh filename="package://mara_description/meshes/MARA_T30.dae" scale="0.001 0.001 0.001"/>
        </geometry>
      </collision>
    </link>
    <gazebo reference="${prefix}motor3_link">
      <material>Gazebo/White</material>
      <selfCollide>True</selfCollide>
    </gazebo>

    <link name="${prefix}motor3_cover">
      <inertial>
        <origin rpy="0 0 0" xyz="8.625E-08 -4.6583E-06 0.03145"/>
        <mass value="3.8"/>
        <inertia ixx="0.04517" ixy="0.00002" ixz="0.0" iyy="0.01587" iyz="0.01444" izz="0.03303"/>
      </inertial>
      <visual>
        <origin rpy="0 0 0" xyz="0 0 0"/>
        <geometry>
          <mesh filename="package://mara_description/meshes/MARA_T30_Black.dae" scale="0.001 0.001 0.001"/>
        </geometry>
        <material name="Gazebo/Black">
          <color rgba="0. 0. 0. 1"/>
        </material>
      </visual>
      <collision>
        <origin rpy="0 0 0" xyz="0 0 0"/>
        <geometry>
          <mesh filename="package://mara_description/meshes/MARA_T30_Black.dae" scale="0.001 0.001 0.001"/>
        </geometry>
      </collision>
    </link>
    <gazebo reference="${prefix}motor3_cover">
      <material>Gazebo/Black</material>
      <selfCollide>True</selfCollide>
    </gazebo>

    <link name="${prefix}motor4_link">
      <inertial>
        <origin rpy="0 0 0" xyz="8.625E-08 -4.6583E-06 0.03145"/>
        <mass value="1.1"/>
        <inertia ixx="0.01464" ixy="0.0" ixz="0.0" iyy="0.00895" iyz="-0.00631" izz="0.00725"/>
      </inertial>
      <visual>
        <origin rpy="0 0 0" xyz="0 0 0"/>
        <geometry>
          <mesh filename="package://mara_description/meshes/MARA_Link2.dae" scale="0.001 0.001 0.001"/>
        </geometry>
        <material name="Gazebo/Black">
          <color rgba="0. 0. 0. 1"/>
        </material>
      </visual>
      <collision>
        <origin rpy="0 0 0" xyz="0 0 0"/>
        <geometry>
          <mesh filename="package://mara_description/meshes/MARA_Link2.dae" scale="0.001 0.001 0.001"/>
        </geometry>
      </collision>
    </link>
    <gazebo reference="${prefix}motor4_link">
      <material>Gazebo/Black</material>
      <selfCollide>True</selfCollide>
    </gazebo>

    <link name="${prefix}motor5_link">
      <inertial>
        <origin rpy="0 0 0" xyz="8.625E-08 -4.6583E-06 0.03145"/>
        <mass value="2.9"/>
        <inertia ixx="0.03406" ixy="0.0" ixz="0.0" iyy="0.01066" iyz="0.00989" izz="0.02563"/>
      </inertial>
      <visual>
        <origin rpy="0 0 0" xyz="0 0 0"/>
        <geometry>
          <mesh filename="package://mara_description/meshes/MARA_T5.4.dae" scale="0.001 0.001 0.001"/>
        </geometry>
        <material name="Gazebo/White">
          <color rgba="0. 0. 0. 1"/>
        </material>
      </visual>
      <collision>
        <origin rpy="0 0 0" xyz="0 0 0"/>
        <geometry>
          <mesh filename="package://mara_description/meshes/MARA_T5.4.dae" scale="0.001 0.001 0.001"/>
        </geometry>
      </collision>
    </link>
    <gazebo reference="${prefix}motor5_link">
      <material>Gazebo/White</material>
      <selfCollide>True</selfCollide>
    </gazebo>

    <link name="${prefix}motor5_cover">
      <inertial>
        <origin rpy="0 0 0" xyz="8.625E-08 -4.6583E-06 0.03145"/>
        <mass value="2.9"/>
        <inertia ixx="0.03406" ixy="0.0" ixz="0.0" iyy="0.01066" iyz="0.00989" izz="0.02563"/>
      </inertial>
      <visual>
        <origin rpy="0 0 0" xyz="0 0 0"/>
        <geometry>
          <mesh filename="package://mara_description/meshes/MARA_T5.4_black.dae" scale="0.001 0.001 0.001"/>
        </geometry>
        <material name="Gazebo/Black">
          <color rgba="0. 0. 0. 1"/>
        </material>
      </visual>
      <collision>
        <origin rpy="0 0 0" xyz="0 0 0"/>
        <geometry>
          <mesh filename="package://mara_description/meshes/MARA_T5.4_black.dae" scale="0.001 0.001 0.001"/>
        </geometry>
      </collision>
    </link>
    <gazebo reference="${prefix}motor5_cover">
      <material>Gazebo/Black</material>
      <selfCollide>True</selfCollide>
    </gazebo>

    <link name="${prefix}motor6_link">
      <inertial>
        <origin rpy="0 0 0" xyz="8.625E-08 -4.6583E-06 0.03145"/>
        <mass value="2.9"/>
        <inertia ixx="0.0005" ixy="0.0" ixz="0.0" iyy="0.0005" iyz="0.0000" izz="0.0003"/>
      </inertial>
      <visual>
        <origin rpy="0 0 0" xyz="0 0 0"/>
        <geometry>
          <mesh filename="package://mara_description/meshes/MARA_GripperAdapter.dae" scale="0.001 0.001 0.001"/>
        </geometry>
        <material name="Gazebo/Black">
          <color rgba="0. 0. 0. 1"/>
      </material>
      </visual>
      <collision>
        <origin rpy="0 0 0" xyz="0 0 0"/>
        <geometry>
          <mesh filename="package://mara_description/meshes/MARA_GripperAdapter.dae" scale="0.001 0.001 0.001"/>
        </geometry>
      </collision>
    </link>
    <gazebo reference="${prefix}motor6_link">
      <material>Gazebo/Black</material>
      <selfCollide>True</selfCollide>
    </gazebo>

    <link name="${prefix}ee_link">
      <visual>
        <geometry>
          <sphere radius="0.01"/>
        </geometry>
        <material name="Gazebo/Grey">
          <color rgba="0. 0. 0. 1"/>
        </material>
      </visual>
    </link>
    <gazebo reference="${prefix}ee_link">
      <material>Gazebo/Blue</material>
      <selfCollide>False</selfCollide>
    </gazebo>

    <joint name="${prefix}joint_bases" type="fixed">
      <origin rpy="0 0 0" xyz="0 0 0.04"/>
      <parent link="${prefix}base_link"/>
      <child link="${prefix}base_robot"/>
    </joint>

    <joint name="${prefix}motor1" type="revolute">
      <origin rpy="0 0 0" xyz="0 0 0.05122"/>
      <parent link="${prefix}base_robot"/>
      <child link="${prefix}motor1_link"/>
      <axis xyz="0 0 -1"/>
      <limit effort="330.0" lower="-3.1416" upper="3.1416" velocity="3.1416"/>
      <dynamics damping="0" friction="0"/>
    </joint>

    <joint name="${prefix}motor1_cover_joint" type="fixed">
      <origin rpy="0 0 0" xyz="0 0 0.0"/>
      <parent link="${prefix}motor1_link"/>
      <child link="${prefix}motor1_cover"/>
    </joint>

    <joint name="${prefix}motor2" type="revolute">
      <origin rpy="0 0 0" xyz="0.118 0 0.1637"/>
      <parent link="${prefix}motor1_link"/>
      <child link="${prefix}motor2_link"/>
      <axis xyz="-1 0 0"/>
      <limit effort="330.0" lower="-3.1416" upper="3.1416" velocity="3.1416"/>
      <dynamics damping="0" friction="0"/>
    </joint>

    <joint name="${prefix}motor3" type="revolute">
      <origin rpy="0 0 0" xyz="-0.009 0 0.2"/>
      <parent link="${prefix}motor2_link"/>
      <child link="${prefix}motor3_link"/>
      <axis xyz="1 0 0"/>
      <limit effort="330.0" lower="-3.1416" upper="3.1416" velocity="3.1416"/>
      <dynamics damping="0" friction="0"/>
    </joint>

    <joint name="${prefix}motor3_cover_joint" type="fixed">
      <origin rpy="0 0 0" xyz="0 0 0.0"/>
      <parent link="${prefix}motor3_link"/>
      <child link="${prefix}motor3_cover"/>
    </joint>

    <joint name="${prefix}motor4" type="revolute">
      <origin rpy="0 0 0" xyz="-0.109255 0 0.149255"/>
      <parent link="${prefix}motor3_link"/>
      <child link="${prefix}motor4_link"/>
      <axis xyz="0 0 -1"/>
      <limit effort="330.0" lower="-3.1416" upper="3.1416" velocity="3.1416"/>
      <dynamics damping="0" friction="0"/>
    </joint>

    <joint name="${prefix}motor5" type="revolute">
      <origin rpy="0 0 0" xyz="0.1054570 0 0.16074"/>
      <parent link="${prefix}motor4_link"/>
      <child link="${prefix}motor5_link"/>
      <axis xyz="1 0 0"/>
      <limit effort="330.0" lower="-3.1416" upper="3.1416" velocity="3.1416"/>
      <dynamics damping="0" friction="0"/>
    </joint>

    <joint name="${prefix}motor5_cover_joint" type="fixed">
      <origin rpy="0 0 0" xyz="0 0 0.0"/>
      <parent link="${prefix}motor5_link"/>
      <child link="${prefix}motor5_cover"/>
    </joint>

    <joint name="${prefix}motor6" type="revolute">
      <origin rpy="0 0 0" xyz="-0.10625569 0 0.14675569"/>
      <parent link="${prefix}motor5_link"/>
      <child link="${prefix}motor6_link"/>
      <axis xyz="0 0 -1"/>
      <limit effort="330.0" lower="-3.1416" upper="3.1416" velocity="3.1416"/>
      <dynamics damping="0" friction="0"/>
    </joint>

    <joint name="${prefix}ee_link" type="fixed">
      <origin rpy="0 -1.57 0" xyz="0 0.0 ${ee_link_distance}"/> <!-- 0.24 -->
      <parent link="${prefix}motor6_link"/>
      <child link="${prefix}ee_link"/>
    </joint>

    <link name="${prefix}tool0"/>
    <joint name="${prefix}${prefix}motor6_link-tool0_fixed_joint" type="fixed">
      <origin rpy="0 -1.57 0" xyz="0 0.0 ${ee_link_distance}"/>
      <parent link="${prefix}${prefix}motor6_link"/>
      <child link="${prefix}tool0"/>
    </joint>

    <xacro:mara_transmission prefix="${prefix}"/>
    <xacro:mara_gazebo prefix="${prefix}"/>

  </xacro:macro>
</robot>
