<?xml version="1.0" ?>
<!-- =================================================================================== -->
<!-- |    This document was autogenerated by xacro from src/mara/mara_description/urdf/two_mara_robots.urdf.xacro | -->
<!-- |    EDITING THIS FILE BY HAND IS NOT RECOMMENDED                                 | -->
<!-- =================================================================================== -->
<robot name="mara" xmlns:xacro="http://ros.org/wiki/xacro">
  <!--
  Author: Alejandro  Hernandez
-->
  <link name="mara1_base_link">
    <inertial>
      <origin rpy="0 0 0" xyz="8.625E-08 -4.6583E-06 0.03145"/>
      <mass value="7.033"/>
      <inertia ixx="0.1478344" ixy="-0.00001" ixz="0.0" iyy="0.14782335" iyz="0.0" izz="0.29471799"/>
    </inertial>
    <visual>
      <origin rpy="0 0 0" xyz="0 0 0"/>
      <geometry>
        <mesh filename="package://mara_description/meshes/Base_plancha.dae" scale="0.001 0.001 0.001"/>
      </geometry>
      <material name="Gazebo/Grey">
        <color rgba="0. 0. 0. 1"/>
      </material>
    </visual>
    <collision>
      <origin rpy="0 0 0" xyz="0 0 0"/>
      <geometry>
        <mesh filename="package://mara_description/meshes/Base_plancha.dae" scale="0.001 0.001 0.001"/>
      </geometry>
    </collision>
  </link>
  <gazebo reference="mara1_base_link">
    <material>Gazebo/Grey</material>
    <selfCollide>True</selfCollide>
  </gazebo>
  <link name="mara1_base_robot">
    <inertial>
      <origin rpy="0 0 0" xyz="8.625E-08 -4.6583E-06 0.03145"/>
      <mass value="7.033"/>
      <inertia ixx="0.1478344" ixy="0.00001" ixz="0.0" iyy="0.14782335" iyz="0.0" izz="0.29471799"/>
    </inertial>
    <visual>
      <origin rpy="0 0 0" xyz="0 0 0"/>
      <geometry>
        <mesh filename="package://mara_description/meshes/Base.dae" scale="0.001 0.001 0.001"/>
      </geometry>
      <material name="Gazebo/Black">
        <color rgba="1. 0. 0. 1.0"/>
      </material>
    </visual>
    <collision>
      <origin rpy="0 0 0" xyz="0 0 0"/>
      <geometry>
        <mesh filename="package://mara_description/meshes/Base.dae" scale="0.001 0.001 0.001"/>
      </geometry>
    </collision>
  </link>
  <gazebo reference="mara1_base_robot">
    <material>Gazebo/Black</material>
    <selfCollide>True</selfCollide>
  </gazebo>
  <link name="mara1_motor1_link">
    <inertial>
      <origin rpy="0 0 0" xyz="0.02066 0 0.12051"/>
      <mass value="5.6"/>
      <inertia ixx="0.0200769278" ixy="-7.72273E-006" ixz="-0.0050158708" iyy="0.0257088151" iyz="5.49229E-006" izz="0.0120821377"/>
    </inertial>
    <visual>
      <origin rpy="0 0 0" xyz="0 0 0"/>
      <geometry>
        <mesh filename="package://mara_description/meshes/MARA_T49.dae" scale="0.001 0.001 0.001"/>
      </geometry>
      <material name="Gazebo/White">
        <color rgba="0. 0. 0. 1"/>
      </material>
    </visual>
    <collision>
      <origin rpy="0 0 0" xyz="0 0 0"/>
      <geometry>
        <mesh filename="package://mara_description/meshes/MARA_T49.dae" scale="0.001 0.001 0.001"/>
      </geometry>
    </collision>
  </link>
  <gazebo reference="mara1_motor1_link">
    <material>Gazebo/White</material>
    <selfCollide>True</selfCollide>
  </gazebo>
  <link name="mara1_motor1_cover">
    <inertial>
      <origin rpy="0 0 0" xyz="0 0 0"/>
      <mass value="0.0"/>
      <inertia ixx="0.0" ixy="0.0" ixz="0.0" iyy="0.0" iyz="0.0" izz="0.0"/>
    </inertial>
    <visual>
      <origin rpy="0 0 0" xyz="0 0 0"/>
      <geometry>
        <mesh filename="package://mara_description/meshes/MARA_T49_Black.dae" scale="0.001 0.001 0.001"/>
      </geometry>
      <material name="Gazebo/Black">
        <color rgba="0. 0. 0. 1"/>
      </material>
    </visual>
    <collision>
      <origin rpy="0 0 0" xyz="0 0 0"/>
      <geometry>
        <mesh filename="package://mara_description/meshes/MARA_T49_Black.dae" scale="0.001 0.001 0.001"/>
      </geometry>
    </collision>
  </link>
  <gazebo reference="mara1_motor1_cover">
    <material>Gazebo/Black</material>
    <selfCollide>True</selfCollide>
  </gazebo>
  <link name="mara1_motor2_link">
    <inertial>
      <origin rpy="0 0 0" xyz="-0.01665 0.0 0.09639"/>
      <mass value="1.24"/>
      <inertia ixx="0.0079614839" ixy="0.000000037" ixz="0.0003203013" iyy="0.007135338" iyz="-0.000001062" izz="0.001111114"/>
    </inertial>
    <visual>
      <origin rpy="0 0 0" xyz="0 0 0"/>
      <geometry>
        <mesh filename="package://mara_description/meshes/MARA_Link1.dae" scale="0.001 0.001 0.001"/>
      </geometry>
      <material name="Gazebo/Black">
        <color rgba="0. 0. 0. 1"/>
      </material>
    </visual>
    <collision>
      <origin rpy="0 0 0" xyz="0 0 0"/>
      <geometry>
        <mesh filename="package://mara_description/meshes/MARA_Link1.dae" scale="0.001 0.001 0.001"/>
      </geometry>
    </collision>
  </link>
  <gazebo reference="mara1_motor2_link">
    <material>Gazebo/Black</material>
    <selfCollide>True</selfCollide>
  </gazebo>
  <link name="mara1_motor3_link">
    <inertial>
      <origin rpy="0 0 0" xyz="-0.08963 0 0.0403"/>
      <mass value="3.95"/>
      <inertia ixx="0.0115136615" ixy="-1.231046E-005" ixz="0.003148516" iyy="0.0149841676" iyz="-8.81378E-006" izz="0.0070387807"/>
    </inertial>
    <visual>
      <origin rpy="0 0 0" xyz="0 0 0"/>
      <geometry>
        <mesh filename="package://mara_description/meshes/MARA_T30.dae" scale="0.001 0.001 0.001"/>
      </geometry>
      <material name="Gazebo/White">
        <color rgba="0. 0. 0. 1"/>
      </material>
    </visual>
    <collision>
      <origin rpy="0 0 0" xyz="0 0 0"/>
      <geometry>
        <mesh filename="package://mara_description/meshes/MARA_T30.dae" scale="0.001 0.001 0.001"/>
      </geometry>
    </collision>
  </link>
  <gazebo reference="mara1_motor3_link">
    <material>Gazebo/White</material>
    <selfCollide>True</selfCollide>
  </gazebo>
  <link name="mara1_motor3_cover">
    <inertial>
      <origin rpy="0 0 0" xyz="0 0 0"/>
      <mass value="0.0"/>
      <inertia ixx="0.0" ixy="0.0" ixz="0.0" iyy="0.0" iyz="0.0" izz="0.0"/>
    </inertial>
    <visual>
      <origin rpy="0 0 0" xyz="0 0 0"/>
      <geometry>
        <mesh filename="package://mara_description/meshes/MARA_T30_Black.dae" scale="0.001 0.001 0.001"/>
      </geometry>
      <material name="Gazebo/Black">
        <color rgba="0. 0. 0. 1"/>
      </material>
    </visual>
    <collision>
      <origin rpy="0 0 0" xyz="0 0 0"/>
      <geometry>
        <mesh filename="package://mara_description/meshes/MARA_T30_Black.dae" scale="0.001 0.001 0.001"/>
      </geometry>
    </collision>
  </link>
  <gazebo reference="mara1_motor3_cover">
    <material>Gazebo/Black</material>
    <selfCollide>True</selfCollide>
  </gazebo>
  <link name="mara1_motor4_link">
    <inertial>
      <origin rpy="0 0 0" xyz="0.06357 0.0 0.05698"/>
      <mass value="1.26"/>
      <inertia ixx="0.005919676" ixy="0.000000923" ixz="-0.0022280208" iyy="0.0068807393" iyz="6.1373E-007" izz="0.00257485"/>
    </inertial>
    <visual>
      <origin rpy="0 0 0" xyz="0 0 0"/>
      <geometry>
        <mesh filename="package://mara_description/meshes/MARA_Link2.dae" scale="0.001 0.001 0.001"/>
      </geometry>
      <material name="Gazebo/Black">
        <color rgba="0. 0. 0. 1"/>
      </material>
    </visual>
    <collision>
      <origin rpy="0 0 0" xyz="0 0 0"/>
      <geometry>
        <mesh filename="package://mara_description/meshes/MARA_Link2.dae" scale="0.001 0.001 0.001"/>
      </geometry>
    </collision>
  </link>
  <gazebo reference="mara1_motor4_link">
    <material>Gazebo/Black</material>
    <selfCollide>True</selfCollide>
  </gazebo>
  <link name="mara1_motor5_link">
    <inertial>
      <origin rpy="0 0 0" xyz="-0.09105 0.0 0.03676"/>
      <mass value="2.85"/>
      <inertia ixx="0.0072829492" ixy="3.77994E-006" ixz="0.0015682105" iyy="0.0098263499" iyz="2.52745E-006" izz="0.0045615321"/>
    </inertial>
    <visual>
      <origin rpy="0 0 0" xyz="0 0 0"/>
      <geometry>
        <mesh filename="package://mara_description/meshes/MARA_T5.4.dae" scale="0.001 0.001 0.001"/>
      </geometry>
      <material name="Gazebo/White">
        <color rgba="0. 0. 0. 1"/>
      </material>
    </visual>
    <collision>
      <origin rpy="0 0 0" xyz="0 0 0"/>
      <geometry>
        <mesh filename="package://mara_description/meshes/MARA_T5.4.dae" scale="0.001 0.001 0.001"/>
      </geometry>
    </collision>
  </link>
  <gazebo reference="mara1_motor5_link">
    <material>Gazebo/White</material>
    <selfCollide>True</selfCollide>
  </gazebo>
  <link name="mara1_motor5_cover">
    <inertial>
      <origin rpy="0 0 0" xyz="0 0 0"/>
      <mass value="0.0"/>
      <inertia ixx="0.0" ixy="0.0" ixz="0.0" iyy="0.0" iyz="0.0" izz="0.0"/>
    </inertial>
    <visual>
      <origin rpy="0 0 0" xyz="0 0 0"/>
      <geometry>
        <mesh filename="package://mara_description/meshes/MARA_T5.4_black.dae" scale="0.001 0.001 0.001"/>
      </geometry>
      <material name="Gazebo/Black">
        <color rgba="0. 0. 0. 1"/>
      </material>
    </visual>
    <collision>
      <origin rpy="0 0 0" xyz="0 0 0"/>
      <geometry>
        <mesh filename="package://mara_description/meshes/MARA_T5.4_black.dae" scale="0.001 0.001 0.001"/>
      </geometry>
    </collision>
  </link>
  <gazebo reference="mara1_motor5_cover">
    <material>Gazebo/Black</material>
    <selfCollide>True</selfCollide>
  </gazebo>
  <!-- dummy link with the required tags-->
  <link name="mara1_motor6_link">
    <inertial>
      <origin rpy="0 0 0" xyz="0 0 0"/>
      <mass value="0.00001"/>
      <inertia ixx="0" ixy="0" ixz="0" iyy="0" iyz="0" izz="0"/>
    </inertial>
    <visual>
      <origin rpy="0 0 0" xyz="0 0 0"/>
      <geometry>
        <sphere radius="0"/>
      </geometry>
    </visual>
    <collision>
      <origin rpy="0 0 0" xyz="0 0 0"/>
      <geometry>
        <sphere radius="0"/>
      </geometry>
    </collision>
  </link>
  <link name="mara1_ee_link"/>
  <joint name="mara1_joint_bases" type="fixed">
    <origin rpy="0 0 0" xyz="0 0 0.04"/>
    <parent link="mara1_base_link"/>
    <child link="mara1_base_robot"/>
  </joint>
  <joint name="mara1_motor1" type="revolute">
    <origin rpy="0 0 0" xyz="0 0 0.05122"/>
    <parent link="mara1_base_robot"/>
    <child link="mara1_motor1_link"/>
    <axis xyz="0 0 1"/>
    <limit effort="104.0" lower="-3.1416" upper="3.1416" velocity="1.57"/>
    <dynamics damping="0" friction="0"/>
  </joint>
  <joint name="mara1_motor1_cover_joint" type="fixed">
    <origin rpy="0 0 0" xyz="0 0 0.0"/>
    <parent link="mara1_motor1_link"/>
    <child link="mara1_motor1_cover"/>
  </joint>
  <joint name="mara1_motor2" type="revolute">
    <origin rpy="0 0 0" xyz="0.118 0 0.1637"/>
    <parent link="mara1_motor1_link"/>
    <child link="mara1_motor2_link"/>
    <axis xyz="1 0 0"/>
    <limit effort="104.0" lower="-2.35" upper="2.35" velocity="1.57"/>
    <dynamics damping="0" friction="0"/>
  </joint>
  <joint name="mara1_motor3" type="revolute">
    <origin rpy="0 0 0" xyz="-0.009 0 0.2"/>
    <parent link="mara1_motor2_link"/>
    <child link="mara1_motor3_link"/>
    <axis xyz="-1 0 0"/>
    <limit effort="69" lower="-2.61" upper="2.61" velocity="1.57"/>
    <dynamics damping="0" friction="0"/>
  </joint>
  <joint name="mara1_motor3_cover_joint" type="fixed">
    <origin rpy="0 0 0" xyz="0 0 0.0"/>
    <parent link="mara1_motor3_link"/>
    <child link="mara1_motor3_cover"/>
  </joint>
  <joint name="mara1_motor4" type="revolute">
    <origin rpy="0 0 0" xyz="-0.109255 0 0.149255"/>
    <parent link="mara1_motor3_link"/>
    <child link="mara1_motor4_link"/>
    <axis xyz="0 0 1"/>
    <limit effort="69" lower="-3.14" upper="3.14" velocity="1.57"/>
    <dynamics damping="0" friction="0"/>
  </joint>
  <joint name="mara1_motor5" type="revolute">
    <origin rpy="0 0 0" xyz="0.1054570 0 0.16074"/>
    <parent link="mara1_motor4_link"/>
    <child link="mara1_motor5_link"/>
    <axis xyz="-1 0 0"/>
    <limit effort="34" lower="-2.56" upper="2.56" velocity="1.57"/>
    <dynamics damping="0" friction="0"/>
  </joint>
  <joint name="mara1_motor5_cover_joint" type="fixed">
    <origin rpy="0 0 0" xyz="0 0 0.0"/>
    <parent link="mara1_motor5_link"/>
    <child link="mara1_motor5_cover"/>
  </joint>
  <joint name="mara1_motor6" type="revolute">
    <origin rpy="0 0 0" xyz="-0.10625569 0 0.14675569"/>
    <parent link="mara1_motor5_link"/>
    <child link="mara1_motor6_link"/>
    <axis xyz="0 0 1"/>
    <limit effort="34" lower="-3.14" upper="3.14" velocity="1.57"/>
    <dynamics damping="0" friction="0"/>
  </joint>
  <joint name="mara1_ee_link" type="fixed">
    <origin rpy="0 -1.57 0" xyz="0 0.0 0.0"/>
    <parent link="mara1_motor6_link"/>
    <child link="mara1_ee_link"/>
  </joint>
  <link name="mara1_tool0"/>
  <joint name="mara1_motor6_link-tool0_fixed_joint" type="fixed">
    <origin rpy="0 -1.57 0" xyz="0 0.0 0.0"/>
    <parent link="mara1_motor6_link"/>
    <child link="mara1_tool0"/>
  </joint>
  <transmission name="mara1_shoulder_pan_trans">
    <type>transmission_interface/SimpleTransmission</type>
    <joint name="mara1_motor1">
      <hardwareInterface>hardware_interface/PositionJointInterface</hardwareInterface>
    </joint>
    <actuator name="mara1_shoulder_pan_motor">
      <mechanicalReduction>1</mechanicalReduction>
    </actuator>
  </transmission>
  <transmission name="mara1_shoulder_lift_trans">
    <type>transmission_interface/SimpleTransmission</type>
    <joint name="mara1_motor2">
      <hardwareInterface>hardware_interface/PositionJointInterface</hardwareInterface>
    </joint>
    <actuator name="mara1_shoulder_lift_motor">
      <mechanicalReduction>1</mechanicalReduction>
    </actuator>
  </transmission>
  <transmission name="mara1_elbow_trans">
    <type>transmission_interface/SimpleTransmission</type>
    <joint name="mara1_motor3">
      <hardwareInterface>hardware_interface/PositionJointInterface</hardwareInterface>
    </joint>
    <actuator name="mara1_elbow_motor">
      <mechanicalReduction>1</mechanicalReduction>
    </actuator>
  </transmission>
  <transmission name="mara1_wrist_1_trans">
    <type>transmission_interface/SimpleTransmission</type>
    <joint name="mara1_motor4">
      <hardwareInterface>hardware_interface/PositionJointInterface</hardwareInterface>
    </joint>
    <actuator name="mara1_wrist_1_motor">
      <mechanicalReduction>1</mechanicalReduction>
    </actuator>
  </transmission>
  <transmission name="mara1_wrist_2_trans">
    <type>transmission_interface/SimpleTransmission</type>
    <joint name="mara1_motor5">
      <hardwareInterface>hardware_interface/PositionJointInterface</hardwareInterface>
    </joint>
    <actuator name="mara1_wrist_2_motor">
      <mechanicalReduction>1</mechanicalReduction>
    </actuator>
  </transmission>
  <transmission name="mara1_wrist_3_trans">
    <type>transmission_interface/SimpleTransmission</type>
    <joint name="mara1_motor6">
      <hardwareInterface>hardware_interface/PositionJointInterface</hardwareInterface>
    </joint>
    <actuator name="mara1_wrist_3_motor">
      <mechanicalReduction>1</mechanicalReduction>
    </actuator>
  </transmission>
  <gazebo>
    <plugin filename="libgazebo_ros_joint_state_publisher.so" name="mara_joint_state">
      <ros>
        <argument>~/out:=joint_states</argument>
      </ros>
      <update_rate>25</update_rate>
      <joint_name>mara1_motor1</joint_name>
      <joint_name>mara1_motor2</joint_name>
      <joint_name>mara1_motor3</joint_name>
      <joint_name>mara1_motor4</joint_name>
      <joint_name>mara1_motor5</joint_name>
      <joint_name>mara1_motor6</joint_name>
      <joint_name>mara1_joint_finger</joint_name>
    </plugin>
    <plugin filename="libmara_gazebo_joint_plugin.so" name="hrim_actuation_servomotor_000000000001">
      <ros/>
      <axis1>mara1_motor2</axis1>
      <axis2>mara1_motor1</axis2>
      <type>series14</type>
    </plugin>
    <plugin filename="libmara_gazebo_joint_plugin.so" name="hrim_actuation_servomotor_000000000002">
      <ros/>
      <axis1>mara1_motor3</axis1>
      <axis2>mara1_motor4</axis2>
      <type>series17</type>
    </plugin>
    <plugin filename="libmara_gazebo_joint_plugin.so" name="hrim_actuation_servomotor_000000000003">
      <ros/>
      <axis1>mara1_motor5</axis1>
      <axis2>mara1_motor6</axis2>
      <type>series20</type>
    </plugin>
  </gazebo>
  <link name="mara2_base_link">
    <inertial>
      <origin rpy="0 0 0" xyz="8.625E-08 -4.6583E-06 0.03145"/>
      <mass value="7.033"/>
      <inertia ixx="0.1478344" ixy="-0.00001" ixz="0.0" iyy="0.14782335" iyz="0.0" izz="0.29471799"/>
    </inertial>
    <visual>
      <origin rpy="0 0 0" xyz="0 0 0"/>
      <geometry>
        <mesh filename="package://mara_description/meshes/Base_plancha.dae" scale="0.001 0.001 0.001"/>
      </geometry>
      <material name="Gazebo/Grey">
        <color rgba="0. 0. 0. 1"/>
      </material>
    </visual>
    <collision>
      <origin rpy="0 0 0" xyz="0 0 0"/>
      <geometry>
        <mesh filename="package://mara_description/meshes/Base_plancha.dae" scale="0.001 0.001 0.001"/>
      </geometry>
    </collision>
  </link>
  <gazebo reference="mara2_base_link">
    <material>Gazebo/Grey</material>
    <selfCollide>True</selfCollide>
  </gazebo>
  <link name="mara2_base_robot">
    <inertial>
      <origin rpy="0 0 0" xyz="8.625E-08 -4.6583E-06 0.03145"/>
      <mass value="7.033"/>
      <inertia ixx="0.1478344" ixy="0.00001" ixz="0.0" iyy="0.14782335" iyz="0.0" izz="0.29471799"/>
    </inertial>
    <visual>
      <origin rpy="0 0 0" xyz="0 0 0"/>
      <geometry>
        <mesh filename="package://mara_description/meshes/Base.dae" scale="0.001 0.001 0.001"/>
      </geometry>
      <material name="Gazebo/Black">
        <color rgba="1. 0. 0. 1.0"/>
      </material>
    </visual>
    <collision>
      <origin rpy="0 0 0" xyz="0 0 0"/>
      <geometry>
        <mesh filename="package://mara_description/meshes/Base.dae" scale="0.001 0.001 0.001"/>
      </geometry>
    </collision>
  </link>
  <gazebo reference="mara2_base_robot">
    <material>Gazebo/Black</material>
    <selfCollide>True</selfCollide>
  </gazebo>
  <link name="mara2_motor1_link">
    <inertial>
      <origin rpy="0 0 0" xyz="0.02066 0 0.12051"/>
      <mass value="5.6"/>
      <inertia ixx="0.0200769278" ixy="-7.72273E-006" ixz="-0.0050158708" iyy="0.0257088151" iyz="5.49229E-006" izz="0.0120821377"/>
    </inertial>
    <visual>
      <origin rpy="0 0 0" xyz="0 0 0"/>
      <geometry>
        <mesh filename="package://mara_description/meshes/MARA_T49.dae" scale="0.001 0.001 0.001"/>
      </geometry>
      <material name="Gazebo/White">
        <color rgba="0. 0. 0. 1"/>
      </material>
    </visual>
    <collision>
      <origin rpy="0 0 0" xyz="0 0 0"/>
      <geometry>
        <mesh filename="package://mara_description/meshes/MARA_T49.dae" scale="0.001 0.001 0.001"/>
      </geometry>
    </collision>
  </link>
  <gazebo reference="mara2_motor1_link">
    <material>Gazebo/White</material>
    <selfCollide>True</selfCollide>
  </gazebo>
  <link name="mara2_motor1_cover">
    <inertial>
      <origin rpy="0 0 0" xyz="0 0 0"/>
      <mass value="0.0"/>
      <inertia ixx="0.0" ixy="0.0" ixz="0.0" iyy="0.0" iyz="0.0" izz="0.0"/>
    </inertial>
    <visual>
      <origin rpy="0 0 0" xyz="0 0 0"/>
      <geometry>
        <mesh filename="package://mara_description/meshes/MARA_T49_Black.dae" scale="0.001 0.001 0.001"/>
      </geometry>
      <material name="Gazebo/Black">
        <color rgba="0. 0. 0. 1"/>
      </material>
    </visual>
    <collision>
      <origin rpy="0 0 0" xyz="0 0 0"/>
      <geometry>
        <mesh filename="package://mara_description/meshes/MARA_T49_Black.dae" scale="0.001 0.001 0.001"/>
      </geometry>
    </collision>
  </link>
  <gazebo reference="mara2_motor1_cover">
    <material>Gazebo/Black</material>
    <selfCollide>True</selfCollide>
  </gazebo>
  <link name="mara2_motor2_link">
    <inertial>
      <origin rpy="0 0 0" xyz="-0.01665 0.0 0.09639"/>
      <mass value="1.24"/>
      <inertia ixx="0.0079614839" ixy="0.000000037" ixz="0.0003203013" iyy="0.007135338" iyz="-0.000001062" izz="0.001111114"/>
    </inertial>
    <visual>
      <origin rpy="0 0 0" xyz="0 0 0"/>
      <geometry>
        <mesh filename="package://mara_description/meshes/MARA_Link1.dae" scale="0.001 0.001 0.001"/>
      </geometry>
      <material name="Gazebo/Black">
        <color rgba="0. 0. 0. 1"/>
      </material>
    </visual>
    <collision>
      <origin rpy="0 0 0" xyz="0 0 0"/>
      <geometry>
        <mesh filename="package://mara_description/meshes/MARA_Link1.dae" scale="0.001 0.001 0.001"/>
      </geometry>
    </collision>
  </link>
  <gazebo reference="mara2_motor2_link">
    <material>Gazebo/Black</material>
    <selfCollide>True</selfCollide>
  </gazebo>
  <link name="mara2_motor3_link">
    <inertial>
      <origin rpy="0 0 0" xyz="-0.08963 0 0.0403"/>
      <mass value="3.95"/>
      <inertia ixx="0.0115136615" ixy="-1.231046E-005" ixz="0.003148516" iyy="0.0149841676" iyz="-8.81378E-006" izz="0.0070387807"/>
    </inertial>
    <visual>
      <origin rpy="0 0 0" xyz="0 0 0"/>
      <geometry>
        <mesh filename="package://mara_description/meshes/MARA_T30.dae" scale="0.001 0.001 0.001"/>
      </geometry>
      <material name="Gazebo/White">
        <color rgba="0. 0. 0. 1"/>
      </material>
    </visual>
    <collision>
      <origin rpy="0 0 0" xyz="0 0 0"/>
      <geometry>
        <mesh filename="package://mara_description/meshes/MARA_T30.dae" scale="0.001 0.001 0.001"/>
      </geometry>
    </collision>
  </link>
  <gazebo reference="mara2_motor3_link">
    <material>Gazebo/White</material>
    <selfCollide>True</selfCollide>
  </gazebo>
  <link name="mara2_motor3_cover">
    <inertial>
      <origin rpy="0 0 0" xyz="0 0 0"/>
      <mass value="0.0"/>
      <inertia ixx="0.0" ixy="0.0" ixz="0.0" iyy="0.0" iyz="0.0" izz="0.0"/>
    </inertial>
    <visual>
      <origin rpy="0 0 0" xyz="0 0 0"/>
      <geometry>
        <mesh filename="package://mara_description/meshes/MARA_T30_Black.dae" scale="0.001 0.001 0.001"/>
      </geometry>
      <material name="Gazebo/Black">
        <color rgba="0. 0. 0. 1"/>
      </material>
    </visual>
    <collision>
      <origin rpy="0 0 0" xyz="0 0 0"/>
      <geometry>
        <mesh filename="package://mara_description/meshes/MARA_T30_Black.dae" scale="0.001 0.001 0.001"/>
      </geometry>
    </collision>
  </link>
  <gazebo reference="mara2_motor3_cover">
    <material>Gazebo/Black</material>
    <selfCollide>True</selfCollide>
  </gazebo>
  <link name="mara2_motor4_link">
    <inertial>
      <origin rpy="0 0 0" xyz="0.06357 0.0 0.05698"/>
      <mass value="1.26"/>
      <inertia ixx="0.005919676" ixy="0.000000923" ixz="-0.0022280208" iyy="0.0068807393" iyz="6.1373E-007" izz="0.00257485"/>
    </inertial>
    <visual>
      <origin rpy="0 0 0" xyz="0 0 0"/>
      <geometry>
        <mesh filename="package://mara_description/meshes/MARA_Link2.dae" scale="0.001 0.001 0.001"/>
      </geometry>
      <material name="Gazebo/Black">
        <color rgba="0. 0. 0. 1"/>
      </material>
    </visual>
    <collision>
      <origin rpy="0 0 0" xyz="0 0 0"/>
      <geometry>
        <mesh filename="package://mara_description/meshes/MARA_Link2.dae" scale="0.001 0.001 0.001"/>
      </geometry>
    </collision>
  </link>
  <gazebo reference="mara2_motor4_link">
    <material>Gazebo/Black</material>
    <selfCollide>True</selfCollide>
  </gazebo>
  <link name="mara2_motor5_link">
    <inertial>
      <origin rpy="0 0 0" xyz="-0.09105 0.0 0.03676"/>
      <mass value="2.85"/>
      <inertia ixx="0.0072829492" ixy="3.77994E-006" ixz="0.0015682105" iyy="0.0098263499" iyz="2.52745E-006" izz="0.0045615321"/>
    </inertial>
    <visual>
      <origin rpy="0 0 0" xyz="0 0 0"/>
      <geometry>
        <mesh filename="package://mara_description/meshes/MARA_T5.4.dae" scale="0.001 0.001 0.001"/>
      </geometry>
      <material name="Gazebo/White">
        <color rgba="0. 0. 0. 1"/>
      </material>
    </visual>
    <collision>
      <origin rpy="0 0 0" xyz="0 0 0"/>
      <geometry>
        <mesh filename="package://mara_description/meshes/MARA_T5.4.dae" scale="0.001 0.001 0.001"/>
      </geometry>
    </collision>
  </link>
  <gazebo reference="mara2_motor5_link">
    <material>Gazebo/White</material>
    <selfCollide>True</selfCollide>
  </gazebo>
  <link name="mara2_motor5_cover">
    <inertial>
      <origin rpy="0 0 0" xyz="0 0 0"/>
      <mass value="0.0"/>
      <inertia ixx="0.0" ixy="0.0" ixz="0.0" iyy="0.0" iyz="0.0" izz="0.0"/>
    </inertial>
    <visual>
      <origin rpy="0 0 0" xyz="0 0 0"/>
      <geometry>
        <mesh filename="package://mara_description/meshes/MARA_T5.4_black.dae" scale="0.001 0.001 0.001"/>
      </geometry>
      <material name="Gazebo/Black">
        <color rgba="0. 0. 0. 1"/>
      </material>
    </visual>
    <collision>
      <origin rpy="0 0 0" xyz="0 0 0"/>
      <geometry>
        <mesh filename="package://mara_description/meshes/MARA_T5.4_black.dae" scale="0.001 0.001 0.001"/>
      </geometry>
    </collision>
  </link>
  <gazebo reference="mara2_motor5_cover">
    <material>Gazebo/Black</material>
    <selfCollide>True</selfCollide>
  </gazebo>
  <!-- dummy link with the required tags-->
  <link name="mara2_motor6_link">
    <inertial>
      <origin rpy="0 0 0" xyz="0 0 0"/>
      <mass value="0.00001"/>
      <inertia ixx="0" ixy="0" ixz="0" iyy="0" iyz="0" izz="0"/>
    </inertial>
    <visual>
      <origin rpy="0 0 0" xyz="0 0 0"/>
      <geometry>
        <sphere radius="0"/>
      </geometry>
    </visual>
    <collision>
      <origin rpy="0 0 0" xyz="0 0 0"/>
      <geometry>
        <sphere radius="0"/>
      </geometry>
    </collision>
  </link>
  <link name="mara2_ee_link"/>
  <joint name="mara2_joint_bases" type="fixed">
    <origin rpy="0 0 0" xyz="0 0 0.04"/>
    <parent link="mara2_base_link"/>
    <child link="mara2_base_robot"/>
  </joint>
  <joint name="mara2_motor1" type="revolute">
    <origin rpy="0 0 0" xyz="0 0 0.05122"/>
    <parent link="mara2_base_robot"/>
    <child link="mara2_motor1_link"/>
    <axis xyz="0 0 1"/>
    <limit effort="104.0" lower="-3.1416" upper="3.1416" velocity="1.57"/>
    <dynamics damping="0" friction="0"/>
  </joint>
  <joint name="mara2_motor1_cover_joint" type="fixed">
    <origin rpy="0 0 0" xyz="0 0 0.0"/>
    <parent link="mara2_motor1_link"/>
    <child link="mara2_motor1_cover"/>
  </joint>
  <joint name="mara2_motor2" type="revolute">
    <origin rpy="0 0 0" xyz="0.118 0 0.1637"/>
    <parent link="mara2_motor1_link"/>
    <child link="mara2_motor2_link"/>
    <axis xyz="1 0 0"/>
    <limit effort="104.0" lower="-2.35" upper="2.35" velocity="1.57"/>
    <dynamics damping="0" friction="0"/>
  </joint>
  <joint name="mara2_motor3" type="revolute">
    <origin rpy="0 0 0" xyz="-0.009 0 0.2"/>
    <parent link="mara2_motor2_link"/>
    <child link="mara2_motor3_link"/>
    <axis xyz="-1 0 0"/>
    <limit effort="69" lower="-2.61" upper="2.61" velocity="1.57"/>
    <dynamics damping="0" friction="0"/>
  </joint>
  <joint name="mara2_motor3_cover_joint" type="fixed">
    <origin rpy="0 0 0" xyz="0 0 0.0"/>
    <parent link="mara2_motor3_link"/>
    <child link="mara2_motor3_cover"/>
  </joint>
  <joint name="mara2_motor4" type="revolute">
    <origin rpy="0 0 0" xyz="-0.109255 0 0.149255"/>
    <parent link="mara2_motor3_link"/>
    <child link="mara2_motor4_link"/>
    <axis xyz="0 0 1"/>
    <limit effort="69" lower="-3.14" upper="3.14" velocity="1.57"/>
    <dynamics damping="0" friction="0"/>
  </joint>
  <joint name="mara2_motor5" type="revolute">
    <origin rpy="0 0 0" xyz="0.1054570 0 0.16074"/>
    <parent link="mara2_motor4_link"/>
    <child link="mara2_motor5_link"/>
    <axis xyz="-1 0 0"/>
    <limit effort="34" lower="-2.56" upper="2.56" velocity="1.57"/>
    <dynamics damping="0" friction="0"/>
  </joint>
  <joint name="mara2_motor5_cover_joint" type="fixed">
    <origin rpy="0 0 0" xyz="0 0 0.0"/>
    <parent link="mara2_motor5_link"/>
    <child link="mara2_motor5_cover"/>
  </joint>
  <joint name="mara2_motor6" type="revolute">
    <origin rpy="0 0 0" xyz="-0.10625569 0 0.14675569"/>
    <parent link="mara2_motor5_link"/>
    <child link="mara2_motor6_link"/>
    <axis xyz="0 0 1"/>
    <limit effort="34" lower="-3.14" upper="3.14" velocity="1.57"/>
    <dynamics damping="0" friction="0"/>
  </joint>
  <joint name="mara2_ee_link" type="fixed">
    <origin rpy="0 -1.57 0" xyz="0 0.0 0.0"/>
    <parent link="mara2_motor6_link"/>
    <child link="mara2_ee_link"/>
  </joint>
  <link name="mara2_tool0"/>
  <joint name="mara2_motor6_link-tool0_fixed_joint" type="fixed">
    <origin rpy="0 -1.57 0" xyz="0 0.0 0.0"/>
    <parent link="mara2_motor6_link"/>
    <child link="mara2_tool0"/>
  </joint>
  <transmission name="mara2_shoulder_pan_trans">
    <type>transmission_interface/SimpleTransmission</type>
    <joint name="mara2_motor1">
      <hardwareInterface>hardware_interface/PositionJointInterface</hardwareInterface>
    </joint>
    <actuator name="mara2_shoulder_pan_motor">
      <mechanicalReduction>1</mechanicalReduction>
    </actuator>
  </transmission>
  <transmission name="mara2_shoulder_lift_trans">
    <type>transmission_interface/SimpleTransmission</type>
    <joint name="mara2_motor2">
      <hardwareInterface>hardware_interface/PositionJointInterface</hardwareInterface>
    </joint>
    <actuator name="mara2_shoulder_lift_motor">
      <mechanicalReduction>1</mechanicalReduction>
    </actuator>
  </transmission>
  <transmission name="mara2_elbow_trans">
    <type>transmission_interface/SimpleTransmission</type>
    <joint name="mara2_motor3">
      <hardwareInterface>hardware_interface/PositionJointInterface</hardwareInterface>
    </joint>
    <actuator name="mara2_elbow_motor">
      <mechanicalReduction>1</mechanicalReduction>
    </actuator>
  </transmission>
  <transmission name="mara2_wrist_1_trans">
    <type>transmission_interface/SimpleTransmission</type>
    <joint name="mara2_motor4">
      <hardwareInterface>hardware_interface/PositionJointInterface</hardwareInterface>
    </joint>
    <actuator name="mara2_wrist_1_motor">
      <mechanicalReduction>1</mechanicalReduction>
    </actuator>
  </transmission>
  <transmission name="mara2_wrist_2_trans">
    <type>transmission_interface/SimpleTransmission</type>
    <joint name="mara2_motor5">
      <hardwareInterface>hardware_interface/PositionJointInterface</hardwareInterface>
    </joint>
    <actuator name="mara2_wrist_2_motor">
      <mechanicalReduction>1</mechanicalReduction>
    </actuator>
  </transmission>
  <transmission name="mara2_wrist_3_trans">
    <type>transmission_interface/SimpleTransmission</type>
    <joint name="mara2_motor6">
      <hardwareInterface>hardware_interface/PositionJointInterface</hardwareInterface>
    </joint>
    <actuator name="mara2_wrist_3_motor">
      <mechanicalReduction>1</mechanicalReduction>
    </actuator>
  </transmission>
  <gazebo>
    <plugin filename="libgazebo_ros_joint_state_publisher.so" name="mara_joint_state">
      <ros>
        <argument>~/out:=joint_states</argument>
      </ros>
      <update_rate>25</update_rate>
      <joint_name>mara2_motor1</joint_name>
      <joint_name>mara2_motor2</joint_name>
      <joint_name>mara2_motor3</joint_name>
      <joint_name>mara2_motor4</joint_name>
      <joint_name>mara2_motor5</joint_name>
      <joint_name>mara2_motor6</joint_name>
      <joint_name>mara2_joint_finger</joint_name>
    </plugin>
    <plugin filename="libmara_gazebo_joint_plugin.so" name="hrim_actuation_servomotor_000000000005">
      <ros/>
      <axis1>mara2_motor2</axis1>
      <axis2>mara2_motor1</axis2>
      <type>series14</type>
    </plugin>
    <plugin filename="libmara_gazebo_joint_plugin.so" name="hrim_actuation_servomotor_000000000006">
      <ros/>
      <axis1>mara2_motor3</axis1>
      <axis2>mara2_motor4</axis2>
      <type>series17</type>
    </plugin>
    <plugin filename="libmara_gazebo_joint_plugin.so" name="hrim_actuation_servomotor_000000000007">
      <ros/>
      <axis1>mara2_motor5</axis1>
      <axis2>mara2_motor6</axis2>
      <type>series20</type>
    </plugin>
  </gazebo>
  <link name="world"/>
  <joint name="world_to_base1_joint" type="fixed">
    <origin rpy="0 0 0" xyz="0 -0.51 0"/>
    <parent link="world"/>
    <child link="mara1_base_link"/>
  </joint>
  <joint name="world_to_base2_joint" type="fixed">
    <origin rpy="0 0 0" xyz="0 0.51 0"/>
    <parent link="world"/>
    <child link="mara2_base_link"/>
  </joint>
</robot>
