<?xml version="1.0" ?>
<!-- =================================================================================== -->
<!-- |    This document was autogenerated by xacro from ros2_mara_ws/src/mara/mara_description/urdf/reinforcement_learning/mara_robot_gripper_140_camera_train.urdf.xacro | -->
<!-- |    EDITING THIS FILE BY HAND IS NOT RECOMMENDED                                 | -->
<!-- =================================================================================== -->
<robot name="mara" xmlns:xacro="http://ros.org/wiki/xacro">
  <link name="motor1_link">
    <inertial>
      <origin rpy="0 0 0" xyz="0.02066 0 0.12051"/>
      <mass value="5.6"/>
      <inertia ixx="0.0200769278" ixy="-7.72273E-006" ixz="-0.0050158708" iyy="0.0257088151" iyz="5.49229E-006" izz="0.0120821377"/>
    </inertial>
    <visual>
      <origin rpy="0 0 0" xyz="0 0 0"/>
      <geometry>
        <mesh filename="package://mara_description/meshes/MARA_T49.dae" scale="0.001 0.001 0.001"/>
      </geometry>
      <material name="Gazebo/White">
        <color rgba="0. 0. 0. 1"/>
      </material>
    </visual>
    <collision>
      <origin rpy="0 0 0" xyz="0 0 0"/>
      <geometry>
        <mesh filename="package://mara_description/meshes/MARA_T49.dae" scale="0.001 0.001 0.001"/>
      </geometry>
    </collision>
  </link>
  <gazebo reference="motor1_link">
    <material>Gazebo/White</material>
    <selfCollide>True</selfCollide>
  </gazebo>
  <link name="motor1_cover">
    <inertial>
      <origin rpy="0 0 0" xyz="0 0 0"/>
      <mass value="0.0"/>
      <inertia ixx="0.0" ixy="0.0" ixz="0.0" iyy="0.0" iyz="0.0" izz="0.0"/>
    </inertial>
    <visual>
      <origin rpy="0 0 0" xyz="0 0 0"/>
      <geometry>
        <mesh filename="package://mara_description/meshes/MARA_T49_Black.dae" scale="0.001 0.001 0.001"/>
      </geometry>
      <material name="Gazebo/Black">
        <color rgba="0. 0. 0. 1"/>
      </material>
    </visual>
    <collision>
      <origin rpy="0 0 0" xyz="0 0 0"/>
      <geometry>
        <mesh filename="package://mara_description/meshes/MARA_T49_Black.dae" scale="0.001 0.001 0.001"/>
      </geometry>
    </collision>
  </link>
  <gazebo reference="motor1_cover">
    <material>Gazebo/Black</material>
    <selfCollide>True</selfCollide>
  </gazebo>
  <link name="motor2_link">
    <inertial>
      <origin rpy="0 0 0" xyz="-0.01665 0.0 0.09639"/>
      <mass value="1.24"/>
      <inertia ixx="0.0079614839" ixy="0.000000037" ixz="0.0003203013" iyy="0.007135338" iyz="-0.000001062" izz="0.001111114"/>
    </inertial>
    <visual>
      <origin rpy="0 0 0" xyz="0 0 0"/>
      <geometry>
        <mesh filename="package://mara_description/meshes/MARA_Link1.dae" scale="0.001 0.001 0.001"/>
      </geometry>
      <material name="Gazebo/Black">
        <color rgba="0. 0. 0. 1"/>
      </material>
    </visual>
    <collision>
      <origin rpy="0 0 0" xyz="0 0 0"/>
      <geometry>
        <mesh filename="package://mara_description/meshes/MARA_Link1.dae" scale="0.001 0.001 0.001"/>
      </geometry>
    </collision>
  </link>
  <gazebo reference="motor2_link">
    <material>Gazebo/Black</material>
    <selfCollide>True</selfCollide>
  </gazebo>
  <link name="motor3_link">
    <inertial>
      <origin rpy="0 0 0" xyz="-0.08963 0 0.0403"/>
      <mass value="3.95"/>
      <inertia ixx="0.0115136615" ixy="-1.231046E-005" ixz="0.003148516" iyy="0.0149841676" iyz="-8.81378E-006" izz="0.0070387807"/>
    </inertial>
    <visual>
      <origin rpy="0 0 0" xyz="0 0 0"/>
      <geometry>
        <mesh filename="package://mara_description/meshes/MARA_T30.dae" scale="0.001 0.001 0.001"/>
      </geometry>
      <material name="Gazebo/White">
        <color rgba="0. 0. 0. 1"/>
      </material>
    </visual>
    <collision>
      <origin rpy="0 0 0" xyz="0 0 0"/>
      <geometry>
        <mesh filename="package://mara_description/meshes/MARA_T30.dae" scale="0.001 0.001 0.001"/>
      </geometry>
    </collision>
  </link>
  <gazebo reference="motor3_link">
    <material>Gazebo/White</material>
    <selfCollide>True</selfCollide>
  </gazebo>
  <link name="motor3_cover">
    <inertial>
      <origin rpy="0 0 0" xyz="0 0 0"/>
      <mass value="0.0"/>
      <inertia ixx="0.0" ixy="0.0" ixz="0.0" iyy="0.0" iyz="0.0" izz="0.0"/>
    </inertial>
    <visual>
      <origin rpy="0 0 0" xyz="0 0 0"/>
      <geometry>
        <mesh filename="package://mara_description/meshes/MARA_T30_Black.dae" scale="0.001 0.001 0.001"/>
      </geometry>
      <material name="Gazebo/Black">
        <color rgba="0. 0. 0. 1"/>
      </material>
    </visual>
    <collision>
      <origin rpy="0 0 0" xyz="0 0 0"/>
      <geometry>
        <mesh filename="package://mara_description/meshes/MARA_T30_Black.dae" scale="0.001 0.001 0.001"/>
      </geometry>
    </collision>
  </link>
  <gazebo reference="motor3_cover">
    <material>Gazebo/Black</material>
    <selfCollide>True</selfCollide>
  </gazebo>
  <link name="motor4_link">
    <inertial>
      <origin rpy="0 0 0" xyz="0.06357 0.0 0.05698"/>
      <mass value="1.26"/>
      <inertia ixx="0.005919676" ixy="0.000000923" ixz="-0.0022280208" iyy="0.0068807393" iyz="6.1373E-007" izz="0.00257485"/>
    </inertial>
    <visual>
      <origin rpy="0 0 0" xyz="0 0 0"/>
      <geometry>
        <mesh filename="package://mara_description/meshes/MARA_Link2.dae" scale="0.001 0.001 0.001"/>
      </geometry>
      <material name="Gazebo/Black">
        <color rgba="0. 0. 0. 1"/>
      </material>
    </visual>
    <collision>
      <origin rpy="0 0 0" xyz="0 0 0"/>
      <geometry>
        <mesh filename="package://mara_description/meshes/MARA_Link2.dae" scale="0.001 0.001 0.001"/>
      </geometry>
    </collision>
  </link>
  <gazebo reference="motor4_link">
    <material>Gazebo/Black</material>
    <selfCollide>True</selfCollide>
  </gazebo>
  <link name="motor5_link">
    <inertial>
      <origin rpy="0 0 0" xyz="-0.09105 0.0 0.03676"/>
      <mass value="2.85"/>
      <inertia ixx="0.0072829492" ixy="3.77994E-006" ixz="0.0015682105" iyy="0.0098263499" iyz="2.52745E-006" izz="0.0045615321"/>
    </inertial>
    <visual>
      <origin rpy="0 0 0" xyz="0 0 0"/>
      <geometry>
        <mesh filename="package://mara_description/meshes/MARA_T5.4.dae" scale="0.001 0.001 0.001"/>
      </geometry>
      <material name="Gazebo/White">
        <color rgba="0. 0. 0. 1"/>
      </material>
    </visual>
    <collision>
      <origin rpy="0 0 0" xyz="0 0 0"/>
      <geometry>
        <mesh filename="package://mara_description/meshes/MARA_T5.4.dae" scale="0.001 0.001 0.001"/>
      </geometry>
    </collision>
  </link>
  <gazebo reference="motor5_link">
    <material>Gazebo/White</material>
    <selfCollide>True</selfCollide>
  </gazebo>
  <link name="motor5_cover">
    <inertial>
      <origin rpy="0 0 0" xyz="0 0 0"/>
      <mass value="0.0"/>
      <inertia ixx="0.0" ixy="0.0" ixz="0.0" iyy="0.0" iyz="0.0" izz="0.0"/>
    </inertial>
    <visual>
      <origin rpy="0 0 0" xyz="0 0 0"/>
      <geometry>
        <mesh filename="package://mara_description/meshes/MARA_T5.4_black.dae" scale="0.001 0.001 0.001"/>
      </geometry>
      <material name="Gazebo/Black">
        <color rgba="0. 0. 0. 1"/>
      </material>
    </visual>
    <collision>
      <origin rpy="0 0 0" xyz="0 0 0"/>
      <geometry>
        <mesh filename="package://mara_description/meshes/MARA_T5.4_black.dae" scale="0.001 0.001 0.001"/>
      </geometry>
    </collision>
  </link>
  <gazebo reference="motor5_cover">
    <material>Gazebo/Black</material>
    <selfCollide>True</selfCollide>
  </gazebo>
  <!-- dummy link with the required tags-->
  <link name="motor6_link">
    <inertial>
      <origin rpy="0 0 0" xyz="0 0 0"/>
      <mass value="0.00001"/>
      <inertia ixx="0" ixy="0" ixz="0" iyy="0" iyz="0" izz="0"/>
    </inertial>
    <visual>
      <origin rpy="0 0 0" xyz="0 0 0"/>
      <geometry>
        <sphere radius="0"/>
      </geometry>
    </visual>
    <collision>
      <origin rpy="0 0 0" xyz="0 0 0"/>
      <geometry>
        <sphere radius="0"/>
      </geometry>
    </collision>
  </link>
  <link name="ee_link">
    <visual>
      <geometry>
        <sphere radius="0.01"/>
      </geometry>
      <material name="Gazebo/Grey">
        <color rgba="0. 0. 0. 1"/>
      </material>
    </visual>
  </link>
  <gazebo reference="ee_link">
    <material>Gazebo/Blue</material>
    <selfCollide>False</selfCollide>
  </gazebo>
  <joint name="motor1_cover_joint" type="fixed">
    <origin rpy="0 0 0" xyz="0 0 0.0"/>
    <parent link="motor1_link"/>
    <child link="motor1_cover"/>
  </joint>
  <joint name="motor2" type="revolute">
    <origin rpy="0 0 0" xyz="0.118 0 0.1637"/>
    <parent link="motor1_link"/>
    <child link="motor2_link"/>
    <axis xyz="1 0 0"/>
    <limit effort="104.0" lower="-2.35" upper="2.35" velocity="1.57"/>
    <dynamics damping="0" friction="0"/>
  </joint>
  <joint name="motor3" type="revolute">
    <origin rpy="0 0 0" xyz="-0.009 0 0.2"/>
    <parent link="motor2_link"/>
    <child link="motor3_link"/>
    <axis xyz="-1 0 0"/>
    <limit effort="69" lower="-2.61" upper="2.61" velocity="1.57"/>
    <dynamics damping="0" friction="0"/>
  </joint>
  <joint name="motor3_cover_joint" type="fixed">
    <origin rpy="0 0 0" xyz="0 0 0.0"/>
    <parent link="motor3_link"/>
    <child link="motor3_cover"/>
  </joint>
  <joint name="motor4" type="revolute">
    <origin rpy="0 0 0" xyz="-0.109255 0 0.149255"/>
    <parent link="motor3_link"/>
    <child link="motor4_link"/>
    <axis xyz="0 0 1"/>
    <limit effort="69" lower="-3.14" upper="3.14" velocity="1.57"/>
    <dynamics damping="0" friction="0"/>
  </joint>
  <joint name="motor5" type="revolute">
    <origin rpy="0 0 0" xyz="0.1054570 0 0.16074"/>
    <parent link="motor4_link"/>
    <child link="motor5_link"/>
    <axis xyz="-1 0 0"/>
    <limit effort="34" lower="-2.56" upper="2.56" velocity="1.57"/>
    <dynamics damping="0" friction="0"/>
  </joint>
  <joint name="motor5_cover_joint" type="fixed">
    <origin rpy="0 0 0" xyz="0 0 0.0"/>
    <parent link="motor5_link"/>
    <child link="motor5_cover"/>
  </joint>
  <joint name="motor6" type="revolute">
    <origin rpy="0 0 0" xyz="-0.10625569 0 0.14675569"/>
    <parent link="motor5_link"/>
    <child link="motor6_link"/>
    <axis xyz="0 0 1"/>
    <limit effort="34" lower="-3.14" upper="3.14" velocity="1.57"/>
    <dynamics damping="0" friction="0"/>
  </joint>
  <joint name="ee_link" type="fixed">
    <origin rpy="0 0 0" xyz="0 0.0 0.24497"/>
    <parent link="motor6_link"/>
    <child link="ee_link"/>
  </joint>
  <transmission name="shoulder_pan_trans">
    <type>transmission_interface/SimpleTransmission</type>
    <joint name="motor1">
      <hardwareInterface>hardware_interface/PositionJointInterface</hardwareInterface>
    </joint>
    <actuator name="shoulder_pan_motor">
      <mechanicalReduction>1</mechanicalReduction>
    </actuator>
  </transmission>
  <transmission name="shoulder_lift_trans">
    <type>transmission_interface/SimpleTransmission</type>
    <joint name="motor2">
      <hardwareInterface>hardware_interface/PositionJointInterface</hardwareInterface>
    </joint>
    <actuator name="shoulder_lift_motor">
      <mechanicalReduction>1</mechanicalReduction>
    </actuator>
  </transmission>
  <transmission name="elbow_trans">
    <type>transmission_interface/SimpleTransmission</type>
    <joint name="motor3">
      <hardwareInterface>hardware_interface/PositionJointInterface</hardwareInterface>
    </joint>
    <actuator name="elbow_motor">
      <mechanicalReduction>1</mechanicalReduction>
    </actuator>
  </transmission>
  <transmission name="wrist_1_trans">
    <type>transmission_interface/SimpleTransmission</type>
    <joint name="motor4">
      <hardwareInterface>hardware_interface/PositionJointInterface</hardwareInterface>
    </joint>
    <actuator name="wrist_1_motor">
      <mechanicalReduction>1</mechanicalReduction>
    </actuator>
  </transmission>
  <transmission name="wrist_2_trans">
    <type>transmission_interface/SimpleTransmission</type>
    <joint name="motor5">
      <hardwareInterface>hardware_interface/PositionJointInterface</hardwareInterface>
    </joint>
    <actuator name="wrist_2_motor">
      <mechanicalReduction>1</mechanicalReduction>
    </actuator>
  </transmission>
  <transmission name="wrist_3_trans">
    <type>transmission_interface/SimpleTransmission</type>
    <joint name="motor6">
      <hardwareInterface>hardware_interface/PositionJointInterface</hardwareInterface>
    </joint>
    <actuator name="wrist_3_motor">
      <mechanicalReduction>1</mechanicalReduction>
    </actuator>
  </transmission>
  <gazebo>
    <plugin filename="libmara_gazebo_joint_training_plugin.so" name="hrim_actuator_rotaryservo_00000000000">
      <ros/>
      <axis1>motor2</axis1>
      <axis2>motor1</axis2>
      <axis3>motor3</axis3>
      <axis4>motor4</axis4>
      <axis5>motor5</axis5>
      <axis6>motor6</axis6>
    </plugin>
  </gazebo>
  <link name="gripper_adapter">
    <inertial>
      <origin rpy="0 0 0" xyz="0 0 0.0173"/>
      <mass value="0.14"/>
      <inertia ixx="0.0001" ixy="0" ixz="0" iyy="0.0001" iyz="0" izz="0.0002"/>
    </inertial>
    <visual>
      <origin rpy="0 0 0" xyz="0 0 0"/>
      <geometry>
        <mesh filename="package://mara_description/meshes/gripper_adapter.dae" scale="0.001 0.001 0.001"/>
      </geometry>
      <material name="Gazebo/Wood">
        <color rgba="0. 0. 0. 1"/>
      </material>
    </visual>
    <collision>
      <origin rpy="0 0 0" xyz="0 0 0"/>
      <geometry>
        <mesh filename="package://mara_description/meshes/gripper_adapter.dae" scale="0.001 0.001 0.001"/>
      </geometry>
    </collision>
  </link>
  <gazebo reference="gripper_adapter">
    <material>Gazebo/Black</material>
    <selfCollide>True</selfCollide>
  </gazebo>
  <link name="camera_support1_link">
    <inertial>
      <origin rpy="0 0 0" xyz="8.625E-08 -4.6583E-06 0.03145"/>
      <mass value="0.00361"/>
      <inertia ixx="266.47E-9" ixy="0.0" ixz="0.0" iyy="115.40E-9" iyz="-0.40E-9" izz="233.53E-9"/>
    </inertial>
    <visual>
      <origin rpy="0 0 0" xyz="0 0 0"/>
      <geometry>
        <mesh filename="package://mara_description/meshes/Camera_Support_1.dae" scale="0.001 0.001 0.001"/>
      </geometry>
      <material name="Gazebo/Wood">
        <color rgba="0. 0. 0. 1"/>
      </material>
    </visual>
    <collision>
      <origin rpy="0 0 0" xyz="0 0 0"/>
      <geometry>
        <mesh filename="package://mara_description/meshes/Camera_Support_1.dae" scale="0.001 0.001 0.001"/>
      </geometry>
    </collision>
  </link>
  <gazebo reference="camera_support1_link">
    <material>Gazebo/Black</material>
    <selfCollide>True</selfCollide>
  </gazebo>
  <link name="camera_support2_link">
    <inertial>
      <origin rpy="0 0 0" xyz="8.625E-08 -4.6583E-06 0.03145"/>
      <mass value="0.00676"/>
      <inertia ixx="584.80E-9" ixy="28.57E-9" ixz="-2.42E-9" iyy="1930.29E-9" iyz="-140.62E-9" izz="2077.50E-9"/>
    </inertial>
    <visual>
      <origin rpy="0 0 0" xyz="0 0 0"/>
      <geometry>
        <mesh filename="package://mara_description/meshes/Camera_Support_2.dae" scale="0.001 0.001 0.001"/>
      </geometry>
      <material name="Gazebo/Wood">
        <color rgba="0. 0. 0. 1"/>
      </material>
    </visual>
    <collision>
      <origin rpy="0 0 0" xyz="0 0 0"/>
      <geometry>
        <mesh filename="package://mara_description/meshes/Camera_Support_2.dae" scale="0.001 0.001 0.001"/>
      </geometry>
    </collision>
  </link>
  <gazebo reference="camera_support2_link">
    <material>Gazebo/Black</material>
    <selfCollide>True</selfCollide>
  </gazebo>
  <joint name="gripper_adapter_to_camera_support1" type="fixed">
    <origin rpy="0 0 0" xyz="0 0.03956 -0.00213"/>
    <parent link="gripper_adapter"/>
    <child link="camera_support1_link"/>
  </joint>
  <joint name="camera_support1_to_support2" type="fixed">
    <origin rpy="0 0 0" xyz="0 0.01029 -0.00128"/>
    <parent link="camera_support1_link"/>
    <child link="camera_support2_link"/>
  </joint>
  <link name="camera_link">
    <inertial>
      <origin rpy="0 0 0" xyz="8.625E-08 -4.6583E-06 0.03145"/>
      <mass value="0.07397"/>
      <inertia ixx="6975.32E-9" ixy="287.18E-9" ixz="25.68E-9" iyy="47975.37E-9" iyz="-25.58E-9" izz="48114.25E-9"/>
    </inertial>
    <visual>
      <origin rpy="0 0 0" xyz="0 0 0"/>
      <geometry>
        <mesh filename="package://mara_description/meshes/Intel_RealSense_Depth_Camera_D435.dae" scale="0.001 0.001 0.001"/>
      </geometry>
      <material name="aluminum">
        <color rgba="0.5 0.5 0.5 1"/>
      </material>
    </visual>
    <collision>
      <origin rpy="0 0 0" xyz="0 0 0"/>
      <geometry>
        <mesh filename="package://mara_description/meshes/Intel_RealSense_Depth_Camera_D435.dae" scale="0.001 0.001 0.001"/>
      </geometry>
    </collision>
  </link>
  <gazebo reference="camera_link">
    <material>Gazebo/Grey</material>
    <selfCollide>True</selfCollide>
  </gazebo>
  <link name="camera_right_depth"/>
  <link name="camera_ir_projector"/>
  <link name="camera_left_depth"/>
  <link name="camera_color"/>
  <gazebo reference="camera_color">
    <sensor name="sensor_camera" type="camera">
      <alwaysOn>true</alwaysOn>
      <!-- <visualize>true</visualize> -->
      <camera>
        <image>
          <width>640</width>
          <height>480</height>
          <format>R8G8B8</format>
        </image>
      </camera>
      <plugin filename="libgazebo_ros_camera.so" name="gazebo_plugins">
        <ros>
          <namespace>rs_camera</namespace>
          <argument>image_raw:=custom_img</argument>
          <argument>camera_info:=custom_info</argument>
        </ros>
        <camera_name>rs_d435</camera_name>
        <frame_name>rs_camera_frame</frame_name>
        <hack_baseline>0.07</hack_baseline>
      </plugin>
    </sensor>
  </gazebo>
  <joint name="camera_to_right_depth" type="fixed">
    <origin rpy="0 0 0" xyz="0.0325 0.024 0.0"/>
    <parent link="camera_link"/>
    <child link="camera_right_depth"/>
  </joint>
  <joint name="camera_to_ir_projector" type="fixed">
    <origin rpy="0 0 0" xyz="0.0115 0.0214 0.0"/>
    <parent link="camera_link"/>
    <child link="camera_ir_projector"/>
  </joint>
  <joint name="camera_to_left_depth" type="fixed">
    <origin rpy="0 0 0" xyz="-0.0175 0.024 0.0"/>
    <parent link="camera_link"/>
    <child link="camera_left_depth"/>
  </joint>
  <joint name="camera_to_color" type="fixed">
    <origin rpy="0.0 0.0 1.57" xyz="-0.0325 0.0214 0.0"/>
    <parent link="camera_link"/>
    <child link="camera_color"/>
  </joint>
  <link name="robotiq_arg2f_base_link">
    <inertial>
      <origin rpy="0 0 0" xyz="-0.00013 0.00011 0.03284"/>
      <mass value="0.52954"/>
      <inertia ixx="573495E-9" ixy="-554E-9" ixz="2628E-9" iyy="681780E-9" iyz="607E-9" izz="483281E-9"/>
    </inertial>
    <visual>
      <origin rpy="0 0 0" xyz="0 0 0"/>
      <geometry>
        <mesh filename="package://robotiq_140_gripper_description/meshes/GRIPPER_base_axis.dae" scale="0.001 0.001 0.001"/>
      </geometry>
      <material name="Gazebo/Black">
        <color rgba="0.1 0.1 0.1 1"/>
      </material>
    </visual>
    <collision>
      <origin rpy="0 0 0" xyz="0 0 0"/>
      <geometry>
        <mesh filename="package://robotiq_140_gripper_description/meshes/GRIPPER_base_axis.dae" scale="0.001 0.001 0.001"/>
      </geometry>
    </collision>
  </link>
  <gazebo reference="robotiq_arg2f_base_link">
    <material>Gazebo/Black</material>
    <selfCollide>True</selfCollide>
  </gazebo>
  <link name="left_outer_knuckle">
    <inertial>
      <origin rpy="0 0 0" xyz="0.01616 0 -0.00133"/>
      <mass value="0.0131"/>
      <inertia ixx="325.5E-9" ixy="0" ixz="197.94E-9" iyy="2306.36E-9" iyz="0" izz="2176E-9"/>
    </inertial>
    <visual>
      <origin rpy="0 0 0" xyz="0 0 0"/>
      <geometry>
        <mesh filename="package://robotiq_140_gripper_description/meshes/robotiq_140_left_outer_knuckle.dae" scale="0.001 0.001 0.001"/>
      </geometry>
      <material name="">
        <color rgba="0.792156862745098 0.819607843137255 0.933333333333333 1"/>
      </material>
    </visual>
    <collision>
      <origin rpy="0 0 0" xyz="0 0 0"/>
      <geometry>
        <mesh filename="package://robotiq_140_gripper_description/meshes/robotiq_140_left_outer_knuckle.dae" scale="0.001 0.001 0.001"/>
      </geometry>
    </collision>
  </link>
  <gazebo reference="left_outer_knuckle">
    <material>Gazebo/Grey</material>
    <selfCollide>True</selfCollide>
  </gazebo>
  <link name="right_outer_knuckle">
    <inertial>
      <origin rpy="0 0 0" xyz="-0.01616 0 -0.00133"/>
      <mass value="0.0131"/>
      <inertia ixx="325.5E-9" ixy="0" ixz="-197.94E-9" iyy="2306.36E-9" iyz="0" izz="2176E-9"/>
    </inertial>
    <visual>
      <origin rpy="0 0 0" xyz="0 0 0"/>
      <geometry>
        <mesh filename="package://robotiq_140_gripper_description/meshes/robotiq_140_right_outer_knuckle.dae" scale="0.001 0.001 0.001"/>
      </geometry>
      <material name="">
        <color rgba="0.792156862745098 0.819607843137255 0.933333333333333 1"/>
      </material>
    </visual>
    <collision>
      <origin rpy="0 0 0" xyz="0 0 0"/>
      <geometry>
        <mesh filename="package://robotiq_140_gripper_description/meshes/robotiq_140_right_outer_knuckle.dae" scale="0.001 0.001 0.001"/>
      </geometry>
    </collision>
  </link>
  <gazebo reference="right_outer_knuckle">
    <material>Gazebo/Grey</material>
    <selfCollide>True</selfCollide>
  </gazebo>
  <link name="left_inner_knuckle">
    <inertial>
      <origin rpy="0 0 0" xyz="0.03332 0 0.0379"/>
      <mass value="0.04476"/>
      <inertia ixx="28054E-9" ixy="0" ixz="-19174E-9" iyy="39758E-9" iyz="0" izz="23453E-9"/>
    </inertial>
    <visual>
      <origin rpy="0 0 0" xyz="0 0 0"/>
      <geometry>
        <mesh filename="package://robotiq_140_gripper_description/meshes/robotiq_140_left_inner_knuckle.dae" scale="0.001 0.001 0.001"/>
      </geometry>
      <material name="Gazebo/Black">
        <color rgba="0.1 0.1 0.1 1"/>
      </material>
    </visual>
    <collision>
      <origin rpy="0 0 0" xyz="0 0 0"/>
      <geometry>
        <mesh filename="package://robotiq_140_gripper_description/meshes/robotiq_140_left_inner_knuckle.dae" scale="0.001 0.001 0.001"/>
      </geometry>
    </collision>
  </link>
  <gazebo reference="left_inner_knuckle">
    <material>Gazebo/Black</material>
    <selfCollide>False</selfCollide>
  </gazebo>
  <link name="right_inner_knuckle">
    <inertial>
      <origin rpy="0 0 0" xyz="-0.03332 0 0.0379"/>
      <mass value="0.04476"/>
      <inertia ixx="28054E-9" ixy="0" ixz="19174E-9" iyy="39758E-9" iyz="0" izz="23453E-9"/>
    </inertial>
    <visual>
      <origin rpy="0 0 0" xyz="0 0 0"/>
      <geometry>
        <mesh filename="package://robotiq_140_gripper_description/meshes/robotiq_140_right_inner_knuckle.dae" scale="0.001 0.001 0.001"/>
      </geometry>
      <material name="Gazebo/Black">
        <color rgba="0.1 0.1 0.1 1"/>
      </material>
    </visual>
    <collision>
      <origin rpy="0 0 0" xyz="0 0 0"/>
      <geometry>
        <mesh filename="package://robotiq_140_gripper_description/meshes/robotiq_140_right_inner_knuckle.dae" scale="0.001 0.001 0.001"/>
      </geometry>
    </collision>
  </link>
  <gazebo reference="right_inner_knuckle">
    <material>Gazebo/Black</material>
    <selfCollide>False</selfCollide>
  </gazebo>
  <link name="left_inner_finger">
    <inertial>
      <origin rpy="0 0 0" xyz="-0.01563 0 0.02522"/>
      <mass value="0.045"/>
      <inertia ixx="26663E-9" ixy="0" ixz="5579E-9" iyy="28009E-9" iyz="0" izz="4368E-9"/>
    </inertial>
    <visual>
      <origin rpy="0 0 0" xyz="0 0 0"/>
      <geometry>
        <mesh filename="package://robotiq_140_gripper_description/meshes/robotiq_140_left_inner_finger.dae" scale="0.001 0.001 0.001"/>
      </geometry>
      <material name="Gazebo/Black">
        <color rgba="0.1 0.1 0.1 1"/>
      </material>
    </visual>
    <collision>
      <origin rpy="0 0 0" xyz="0 0 0"/>
      <geometry>
        <mesh filename="package://robotiq_140_gripper_description/meshes/robotiq_140_left_inner_finger.dae" scale="0.001 0.001 0.001"/>
      </geometry>
    </collision>
  </link>
  <gazebo reference="left_inner_finger">
    <material>Gazebo/Black</material>
    <selfCollide>False</selfCollide>
  </gazebo>
  <link name="right_inner_finger">
    <inertial>
      <origin rpy="0 0 0" xyz="0.01563 0 0.02522"/>
      <mass value="0.045"/>
      <inertia ixx="26663E-9" ixy="0" ixz="-5579E-9" iyy="28009E-9" iyz="0" izz="4368E-9"/>
    </inertial>
    <visual>
      <origin rpy="0 0 0" xyz="0 0 0"/>
      <geometry>
        <mesh filename="package://robotiq_140_gripper_description/meshes/robotiq_140_right_inner_finger.dae" scale="0.001 0.001 0.001"/>
      </geometry>
      <material name="Gazebo/Black">
        <color rgba="0.1 0.1 0.1 1"/>
      </material>
    </visual>
    <collision>
      <origin rpy="0 0 0" xyz="0 0 0"/>
      <geometry>
        <mesh filename="package://robotiq_140_gripper_description/meshes/robotiq_140_right_inner_finger.dae" scale="0.001 0.001 0.001"/>
      </geometry>
    </collision>
  </link>
  <gazebo reference="right_inner_finger">
    <material>Gazebo/Black</material>
    <selfCollide>False</selfCollide>
  </gazebo>
  <link name="left_outer_finger">
    <inertial>
      <origin rpy="0 0 0" xyz="0.01482 0 0.03451"/>
      <mass value="0.07637"/>
      <inertia ixx="45513E-9" ixy="0" ixz="-20691E-9" iyy="52570E-9" iyz="0" izz="17804E-9"/>
    </inertial>
    <visual>
      <origin rpy="0 0 0" xyz="0 0 0"/>
      <geometry>
        <mesh filename="package://robotiq_140_gripper_description/meshes/robotiq_140_left_outer_finger.dae" scale="0.001 0.001 0.001"/>
      </geometry>
      <material name="Gazebo/Black">
        <color rgba="0.1 0.1 0.1 1"/>
      </material>
    </visual>
    <collision>
      <origin rpy="0 0 0" xyz="0 0 0"/>
      <geometry>
        <mesh filename="package://robotiq_140_gripper_description/meshes/robotiq_140_left_outer_finger.dae" scale="0.001 0.001 0.001"/>
      </geometry>
    </collision>
  </link>
  <gazebo reference="left_outer_finger">
    <material>Gazebo/Black</material>
    <selfCollide>True</selfCollide>
  </gazebo>
  <link name="right_outer_finger">
    <inertial>
      <origin rpy="0 0 0" xyz="-0.01482 0 0.03451"/>
      <mass value="0.07637"/>
      <inertia ixx="45513E-9" ixy="0" ixz="20691E-9" iyy="52570E-9" iyz="0" izz="17804E-9"/>
    </inertial>
    <visual>
      <origin rpy="0 0 0" xyz="0 0 0"/>
      <geometry>
        <mesh filename="package://robotiq_140_gripper_description/meshes/robotiq_140_right_outer_finger.dae" scale="0.001 0.001 0.001"/>
      </geometry>
      <material name="Gazebo/Black">
        <color rgba="0.1 0.1 0.1 1"/>
      </material>
    </visual>
    <collision>
      <origin rpy="0 0 0" xyz="0 0 0"/>
      <geometry>
        <mesh filename="package://robotiq_140_gripper_description/meshes/robotiq_140_right_outer_finger.dae" scale="0.001 0.001 0.001"/>
      </geometry>
    </collision>
  </link>
  <gazebo reference="right_outer_finger">
    <material>Gazebo/Black</material>
    <selfCollide>True</selfCollide>
  </gazebo>
  <joint name="robotiq_arg2f_base_to_left_outer_knuckle" type="revolute">
    <origin rpy="0 0 0" xyz="0.0306 0 0.05466"/>
    <parent link="robotiq_arg2f_base_link"/>
    <child link="left_outer_knuckle"/>
    <axis xyz="0 -1 0"/>
    <limit effort="18.65" lower="0" upper="0.78574722925" velocity="2.0"/>
    <mimic joint="joint_finger" multiplier="1" offset="0"/>
  </joint>
  <joint name="joint_finger" type="revolute">
    <origin rpy="0 0 0" xyz="-0.0306 0 0.05466"/>
    <parent link="robotiq_arg2f_base_link"/>
    <child link="right_outer_knuckle"/>
    <axis xyz="0 1 0"/>
    <limit effort="18.65" lower="0" upper="0.78574722925" velocity="3.54"/>
  </joint>
  <joint name="robotiq_arg2f_base_to_left_inner_knuckle" type="revolute">
    <origin rpy="0 0 0" xyz="0.0127 0 0.06118"/>
    <parent link="robotiq_arg2f_base_link"/>
    <child link="left_inner_knuckle"/>
    <axis xyz="0 -1 0"/>
    <limit effort="18.65" lower="0" upper="0.78574722925" velocity="3.54"/>
    <mimic joint="joint_finger" multiplier="1" offset="0"/>
  </joint>
  <joint name="robotiq_arg2f_base_to_right_inner_knuckle" type="revolute">
    <origin rpy="0 0 0" xyz="-0.0127 0 0.06118"/>
    <parent link="robotiq_arg2f_base_link"/>
    <child link="right_inner_knuckle"/>
    <axis xyz="0 1 0"/>
    <limit effort="18.65" lower="0" upper="0.78574722925" velocity="3.54"/>
    <mimic joint="joint_finger" multiplier="1" offset="0"/>
  </joint>
  <joint name="left_outer_knuckle_to_finger" type="fixed">
    <origin rpy="0 0 0" xyz="0.03142 0 -0.00453"/>
    <parent link="left_outer_knuckle"/>
    <child link="left_outer_finger"/>
  </joint>
  <joint name="right_outer_knuckle_to_finger" type="fixed">
    <origin rpy="0 0 0" xyz="-0.03142 0 -0.00453"/>
    <parent link="right_outer_knuckle"/>
    <child link="right_outer_finger"/>
  </joint>
  <joint name="left_outer_finger_to_inner" type="revolute">
    <origin rpy="0 0 0" xyz="0.03543 0 0.0789"/>
    <parent link="left_outer_finger"/>
    <child link="left_inner_finger"/>
    <axis xyz="0 1 0"/>
    <limit effort="18.65" lower="0" upper="0.78574722925" velocity="3.54"/>
    <mimic joint="joint_finger" multiplier="1" offset="0"/>
  </joint>
  <joint name="right_outer_finger_to_inner" type="revolute">
    <origin rpy="0 0 0" xyz="-0.03543 0 0.0789"/>
    <parent link="right_outer_finger"/>
    <child link="right_inner_finger"/>
    <axis xyz="0 -1 0"/>
    <limit effort="18.65" lower="0" upper="0.78574722925" velocity="3.54"/>
    <mimic joint="joint_finger" multiplier="1" offset="0"/>
  </joint>
  <gazebo>
    <joint name="left_inner_knuckle_to_finger" type="revolute">
      <pose frame="">-0.0179 0 0.00652 0 0 0</pose>
      <parent>left_inner_knuckle</parent>
      <child>left_inner_finger</child>
      <axis>
        <xyz>0 1 0</xyz>
        <limit>
          <lower>0</lower>
          <upper>0.78574722925</upper>
          <velocity>3.54</velocity>
          <effort>18.65</effort>
        </limit>
      </axis>
    </joint>
    <joint name="right_inner_knuckle_to_finger" type="revolute">
      <pose frame="">0.0179 0 0.00652 0 0 0</pose>
      <parent>right_inner_knuckle</parent>
      <child>right_inner_finger</child>
      <axis>
        <xyz>0 -1 0</xyz>
        <limit>
          <lower>0</lower>
          <upper>0.78574722925</upper>
          <velocity>3.54</velocity>
          <effort>18.65</effort>
        </limit>
      </axis>
    </joint>
    <plugin filename="librobotiq_gripper_gazebo_plugin.so" name="hrim_actuator_gripper_000000000004">
      <kp>600</kp>
      <ki>0.1</ki>
      <kd>0.01</kd>
      <min_velocity>30</min_velocity>
      <max_velocity>250</max_velocity>
      <radius>156</radius>
      <joint>robotiq_arg2f_base_to_left_inner_knuckle</joint>
      <joint>robotiq_arg2f_base_to_left_outer_knuckle</joint>
      <joint>robotiq_arg2f_base_to_right_inner_knuckle</joint>
      <joint>joint_finger</joint>
    </plugin>
  </gazebo>
  <link name="world"/>
  <link name="base_robot">
    <inertial>
      <origin rpy="0 0 0" xyz="8.625E-08 -4.6583E-06 0.03145"/>
      <mass value="7.033"/>
      <inertia ixx="0.1478344" ixy="0.00001" ixz="0.0" iyy="0.14782335" iyz="0.0" izz="0.29471799"/>
    </inertial>
    <visual>
      <origin rpy="0 0 0" xyz="0 0 0"/>
      <geometry>
        <mesh filename="package://mara_description/meshes/Base.dae" scale="0.001 0.001 0.001"/>
      </geometry>
      <material name="Gazebo/Black">
        <color rgba="1. 0. 0. 1.0"/>
      </material>
    </visual>
    <collision>
      <origin rpy="0 0 0" xyz="0 0 0"/>
      <geometry>
        <mesh filename="package://mara_description/meshes/Base.dae" scale="0.001 0.001 0.001"/>
      </geometry>
    </collision>
  </link>
  <gazebo reference="base_robot">
    <material>Gazebo/Black</material>
    <selfCollide>True</selfCollide>
  </gazebo>
  <link name="robotiq_adapter_link">
    <inertial>
      <origin rpy="0 0 0" xyz="0 0 -0.0253"/>
      <mass value="0.317"/>
      <inertia ixx="298526E-9" ixy="3928E-9" ixz="-926E-9" iyy="354661E-9" iyz="42E-9" izz="415572E-9"/>
    </inertial>
    <visual>
      <origin rpy="0 0 0" xyz="0 0 0"/>
      <geometry>
        <mesh filename="package://mara_description/meshes/robotiq_adapter.dae" scale="0.001 0.001 0.001"/>
      </geometry>
      <material name="Gazebo/Black">
        <color rgba="0.0 0.0 0.0 1"/>
      </material>
    </visual>
    <collision>
      <origin rpy="0 0 0" xyz="0 0 0"/>
      <geometry>
        <mesh filename="package://mara_description/meshes/robotiq_adapter.dae" scale="0.001 0.001 0.001"/>
      </geometry>
    </collision>
  </link>
  <gazebo reference="robotiq_adapter_link">
    <material>Gazebo/Black</material>
    <selfCollide>True</selfCollide>
  </gazebo>
  <joint name="world_to_base_robot" type="fixed">
    <origin rpy="0 0 0" xyz="0 0 0"/>
    <parent link="world"/>
    <child link="base_robot"/>
  </joint>
  <joint name="motor1" type="revolute">
    <origin rpy="0 0 0" xyz="0 0 0.05122"/>
    <parent link="base_robot"/>
    <child link="motor1_link"/>
    <axis xyz="0 0 1"/>
    <limit effort="104.0" lower="-3.1416" upper="3.1416" velocity="1.57"/>
    <dynamics damping="0" friction="0"/>
  </joint>
  <joint name="motor6_to_gripper_adapter" type="fixed">
    <origin rpy="0 0 0" xyz="0 0 -0.02026"/>
    <parent link="motor6_link"/>
    <child link="gripper_adapter"/>
  </joint>
  <joint name="gripper_adapter_to_robotiq_adapter" type="fixed">
    <origin rpy="0 0 0" xyz="0 0 0.05679"/>
    <parent link="gripper_adapter"/>
    <child link="robotiq_adapter_link"/>
  </joint>
  <joint name="camera_support2_to_camera" type="fixed">
    <origin rpy="0 0 0" xyz="0 0.018 0.012"/>
    <parent link="camera_support2_link"/>
    <child link="camera_link"/>
  </joint>
  <joint name="robotiq_adapter_link_to_robotiq_arg2f_base_link" type="fixed">
    <origin rpy="0 0 0" xyz=" 0 0 0"/>
    <parent link="robotiq_adapter_link"/>
    <child link="robotiq_arg2f_base_link"/>
  </joint>
</robot>
